Workbook
Name _Fill: #REF!
Name _Fill: #REF!
Name _g20616: #REF!
Name _g20616: #REF!
Name a: #REF!
Name a: #REF!
Name AccessDatabase: "C:\My Documents\99\FAFORM99.mdb"
Name Bust: #REF!
Name Bust: #REF!
Name Continue: #REF!
Name Continue: #REF!
Name Document_array: {"HM PST Agt 2005.xls"}
Name Documents_array: #REF!
Name Documents_array: #REF!
Name EX: 'Data Down'!#REF!
Name h: #REF!
Name h: #REF!
Name Hello: #REF!
Name Hello: #REF!
Name m: #REF!
Name m: #REF!
Name MM: #REF!
Name MM: #REF!
Name N: #REF!
Name n: #REF!
Name n: #REF!
Name OT: 'Data Down'!$S:$S
Name Print_Area_MI: #REF!
Name Print_Area_MI: #REF!
Name Print_Titles_MI: #REF!
Name Print_Titles_MI: #REF!
Name TaxTV: 10%
Name TaxXL: 5%
Name Test: #REF!
Name Test: #REF!
Name Z_DC2F2F0B_6687_4232_9497_BBA352865051_.wvu.Cols: HM_Unit!$P:$AK

Sheet FOR DAILY
A1: ID UNIT | B1: AWAL BULAN | C1: HM RUNNING | D1: BD | E1: RUNNING
A2: DT TATA 035 | B2: =VLOOKUP(A2,HM_Unit!$A$2:$D$107,4,0) -> 14778 | C2: =VLOOKUP(A2,'Summary KPI'!$B$10:$E$112,4,0) -> 14781 | D2: =SUMIF('Data Down'!$D:$D,A2,'Data Down'!N:N) -> 7.8500126 | E2: =C2-B2 -> 3
A3: DT TATA 064 | B3: =VLOOKUP(A3,HM_Unit!$A$2:$D$107,4,0) -> 16204 | C3: =VLOOKUP(A3,'Summary KPI'!$B$10:$E$112,4,0) -> 16316 | D3: =SUMIF('Data Down'!$D:$D,A3,'Data Down'!N:N) -> 5.2666751 | E3: =C3-B3 -> 112
A4: DT TATA 070 | B4: =VLOOKUP(A4,HM_Unit!$A$2:$D$107,4,0) -> 13239 | C4: =VLOOKUP(A4,'Summary KPI'!$B$10:$E$112,4,0) -> 13404 | D4: =SUMIF('Data Down'!$D:$D,A4,'Data Down'!N:N) -> 17.583361 | E4: =C4-B4 -> 165
A5: DT TATA 078 | B5: =VLOOKUP(A5,HM_Unit!$A$2:$D$107,4,0) -> 13225 | C5: =VLOOKUP(A5,'Summary KPI'!$B$10:$E$112,4,0) -> 13385 | D5: =SUMIF('Data Down'!$D:$D,A5,'Data Down'!N:N) -> 5.9500095 | E5: =C5-B5 -> 160
A6: DT TATA 085 | B6: =VLOOKUP(A6,HM_Unit!$A$2:$D$107,4,0) -> 15461 | C6: =VLOOKUP(A6,'Summary KPI'!$B$10:$E$112,4,0) -> 15612 | D6: =SUMIF('Data Down'!$D:$D,A6,'Data Down'!N:N) -> 4.1333399 | E6: =C6-B6 -> 151
A7: DT TATA 086 | B7: =VLOOKUP(A7,HM_Unit!$A$2:$D$107,4,0) -> 15411 | C7: =VLOOKUP(A7,'Summary KPI'!$B$10:$E$112,4,0) -> 15433 | D7: =SUMIF('Data Down'!$D:$D,A7,'Data Down'!N:N) -> 6.9500111 | E7: =C7-B7 -> 22
A8: DT TATA 088 | B8: =VLOOKUP(A8,HM_Unit!$A$2:$D$107,4,0) -> 15743 | C8: =VLOOKUP(A8,'Summary KPI'!$B$10:$E$112,4,0) -> 15797 | D8: =SUMIF('Data Down'!$D:$D,A8,'Data Down'!N:N) -> 13.416688 | E8: =C8-B8 -> 54
A9: DT MERCY 037 | B9: =VLOOKUP(A9,HM_Unit!$A$2:$D$107,4,0) -> 15606 | C9: =VLOOKUP(A9,'Summary KPI'!$B$10:$E$112,4,0) -> 15945 | D9: =SUMIF('Data Down'!$D:$D,A9,'Data Down'!N:N) -> 163.06693 | E9: =C9-B9 -> 339
A10: DT MERCY 038 | B10: =VLOOKUP(A10,HM_Unit!$A$2:$D$107,4,0) -> 18765 | C10: =VLOOKUP(A10,'Summary KPI'!$B$10:$E$112,4,0) -> 19158 | D10: =SUMIF('Data Down'!$D:$D,A10,'Data Down'!N:N) -> 55.866756 | E10: =C10-B10 -> 393
A11: DT MERCY 039 | B11: =VLOOKUP(A11,HM_Unit!$A$2:$D$107,4,0) -> 18054 | C11: =VLOOKUP(A11,'Summary KPI'!$B$10:$E$112,4,0) -> 18302 | D11: =SUMIF('Data Down'!$D:$D,A11,'Data Down'!N:N) -> 260.33375 | E11: =C11-B11 -> 248
A12: DT MERCY 040 | B12: =VLOOKUP(A12,HM_Unit!$A$2:$D$107,4,0) -> 17501 | C12: =VLOOKUP(A12,'Summary KPI'!$B$10:$E$112,4,0) -> 17890 | D12: =SUMIF('Data Down'!$D:$D,A12,'Data Down'!N:N) -> 60.700097 | E12: =C12-B12 -> 389
A13: DT MERCY 041 | B13: =VLOOKUP(A13,HM_Unit!$A$2:$D$107,4,0) -> 17922 | C13: =VLOOKUP(A13,'Summary KPI'!$B$10:$E$112,4,0) -> 18308 | D13: =SUMIF('Data Down'!$D:$D,A13,'Data Down'!N:N) -> 34.916723 | E13: =C13-B13 -> 386
... A104: DT 52 KPB | B104: =VLOOKUP(A104,HM_Unit!$A$2:$D$107,4,0) -> 17347 | C104: =VLOOKUP(A104,'Summary KPI'!$B$10:$E$112,4,0) -> 17780 | D104: =SUMIF('Data Down'!$D:$D,A104,'Data Down'!N:N) -> 15.183358 | E104: =C104-B104 -> 433

Sheet Summary KPI
O1: TRUE
B4: 1 | C4: 2 | D4: 3 | E4: 4 | F4: 5 | G4: 6 | H4: 7 | I4: 8 | J4: 9 | K4: 10 | L4: 11 | M4: 12 | N4: 13 | O4: 14 | P4: 15 | Q4: 16 | R4: 17 | S4: 18 | T4: 19 | U4: 20 | V4: 21 | W4: 22 | X4: 23 | Y4: 24 | Z4: 25 | AA4: 26 | AB4: 27 | AC4: 28 | AD4: 29 | AE4: 30 | AF4: 31 | AG4: 32 | AH4: 33 | AI4: 34 | AJ4: 35 | AK4: 36 | AL4: 37 | AM4: 38 | AN4: 39 | AO4: 40
D5: start | E5: 46113 | F5: end | G5: 46142 | H5: =(G5-E5)+1 -> 30 | I5: =G5 -> 46142 | J5: =(I5-E5)+1 -> 30
A6: No. | B6: Unit Code | C6: Unit Model | D6: Hour Meter Reading | F6: Work | G6: B/Down | H6: Accident | I6: Wet | J6: Stand By | K6: MTD | L6: MOHH | M6: Stoppage Frequencies | Q6: Stoppage Duration | U6: Delay Type | AD6: Availability & Utillity | AH6: MTBS | AI6: MTBF | AJ6: MTTR | AK6: D (%) | AL6: Sched. Event (%) | AM6: Unschd. Event (%) | AN6: Sched. Dur (%) | AO6: Unschd. Dur (%)
U7: WP | V7: WL | W7: CW | X7: WT | Y7: WN | Z7: WR | AA7: OSR | AB7: ACC | AC7: WA | AD7: PA | AE7: UA | AF7: MA | AG7: EU
D8: Start | E8: Finish | M8: D | N8: P | O8: UM | P8: OM | Q8: D | R8: P | S8: UM | T8: OM | U8: Wait Part | V8: Wait Labour | W8: Claim warranty | X8: Wait Tool | Y8: Work Normal | Z8: Waiting Rain | AA8: Waiting Out Site Repair | AB8: Waiting Accident | AC8: Waiting Access | AQ8: bd | AR8: FRE
A9: =A6 -> No. | B9: =B6 -> Unit Code | C9: Unit Model | D9: Hour Meter Reading | E9: =E6 -> 0 | F9: =F6 -> Work | G9: =G6 -> B/Down | H9: =H6 -> Accident | I9: Wet | J9: =J6 -> Stand By | L9: =L6 -> MOHH | U9: =U6 -> Delay Type | V9: =V6 -> 0 | W9: =X6 -> 0 | X9: =Y6 -> 0 | Y9: =Z6 -> 0 | Z9: =AB6 -> 0 | AA9: =#REF! -> #REF! | AB9: =#REF! -> #REF! | AC9: =#REF! -> #REF! | AD9: PA | AE9: PU | AF9: MA | AG9: PU | AH9: =AH6 -> MTBS | AI9: =AI6 -> MTBF | AJ9: =AJ6 -> MTTR | AK9: =AK6 -> D (%) | AL9: =AL6 -> Sched. Event (%) | AM9: =AM6 -> Unschd. Event (%) | AN9: =AN6 -> Sched. Dur (%) | AO9: =AO6 -> Unschd. Dur (%)
A10: 1 | B10: DT TATA 035 | C10: =VLOOKUP(B10,Sort!B:C,2,FALSE) -> Prima LX 2528 | D10: {=INDEX(HM_Unit!D:D,MATCH('Summary KPI'!B10,HM_Unit!A:A,0))} -> 14778 | E10: {=INDEX(HM_Unit!CD:CD,MATCH('Summary KPI'!B10,HM_Unit!A:A,0))} -> 14781 | F10: =E10-D10 -> 3 | G10: =SUM(R10:S10) -> 7.8500126 | H10: =Q10 -> 0 | I10: =+Z10 -> 0 | J10: =L10-F10-I10-G10-H10 -> 709.14999 | K10: =$J$5*24 -> 720 | L10: =$H$5*24 -> 720 | M10: =SUMIFS('Data Down'!U:U,'Data Down'!D:D,'Summary KPI'!B10,'Data Down'!Q:Q,'Summary KPI'!$M$8,'Data Down'!$C:$C,"<="&'Summary KPI'!$G$5,'Data Down'!$C:$C,">="&'Summary KPI'!$E$5) -> 0 | N10: =SUMIFS('Data Down'!U:U,'Data Down'!D:D,'Summary KPI'!B10,'Data Down'!Q:Q,'Summary KPI'!$N$8,'Data Down'!$C:$C,"<="&'Summary KPI'!$G$5,'Data Down'!$C:$C,">="&'Summary KPI'!$E$5) -> 1 | O10: =SUMIFS('Data Down'!U:U,'Data Down'!D:D,'Summary KPI'!B10,'Data Down'!Q:Q,'Summary KPI'!$O$8,'Data Down'!$C:$C,"<="&'Summary KPI'!$G$5,'Data Down'!$C:$C,">="&'Summary KPI'!$E$5) -> 2 | P10: =SUMIFS('Data Down'!U:U,'Data Down'!D:D,'Summary KPI'!B10,'Data Down'!Q:Q,'Summary KPI'!$P$8,'Data Down'!$C:$C,"<="&'Summary KPI'!$G$5,'Data Down'!$C:$C,">="&'Summary KPI'!$E$5) -> 0 | Q10: =SUMIFS('Data Down'!N:N,'Data Down'!$D:$D,'Summary KPI'!$B10,'Data Down'!$Q:$Q,'Summary KPI'!$Q$8,'Data Down'!$C:$C,"<="&'Summary KPI'!$G$5,'Data Down'!$C:$C,">="&'Summary KPI'!$E$5) -> 0 | R10: =SUMIFS('Data Down'!N:N,'Data Down'!D:D,'Summary KPI'!B10,'Data Down'!Q:Q,'Summary KPI'!$R$8,'Data Down'!$C:$C,"<="&'Summary KPI'!$G$5,'Data Down'!$C:$C,">="&'Summary KPI'!$E$5) -> 0.91666813 | S10: =SUMIFS('Data Down'!N:N,'Data Down'!D:D,'Summary KPI'!B10,'Data Down'!Q:Q,'Summary KPI'!$S$8,'Data Down'!$C:$C,"<="&'Summary KPI'!$G$5,'Data Down'!$C:$C,">="&'Summary KPI'!$E$5) -> 6.9333444 | T10: =SUMIFS('Data Down'!N:N,'Data Down'!D:D,'Summary KPI'!B10,'Data Down'!Q:Q,'Summary KPI'!$T$8,'Data Down'!$C:$C,"<="&'Summary KPI'!$G$5,'Data Down'!$C:$C,">="&'Summary KPI'!$E$5) -> 0 | U10: =+SUMIFS('Data Down'!$N:$N,'Data Down'!$D:$D,'Summary KPI'!B10,'Data Down'!$R:$R,'Summary KPI'!$U$7,'Data Down'!$C:$C,"<="&'Summary KPI'!$G$5,'Data Down'!$C:$C,">="&'Summary KPI'!$E$5) -> 0 | V10: =+SUMIFS('Data Down'!$N:$N,'Data Down'!$D:$D,'Summary KPI'!B10,'Data Down'!$R:$R,'Summary KPI'!$V$7,'Data Down'!$C:$C,"<="&'Summary KPI'!$G$5,'Data Down'!$C:$C,">="&'Summary KPI'!$E$5) -> 0 | W10: =+SUMIFS('Data Down'!$N:$N,'Data Down'!$D:$D,'Summary KPI'!B10,'Data Down'!$R:$R,'Summary KPI'!$W$7,'Data Down'!$C:$C,"<="&'Summary KPI'!$G$5,'Data Down'!$C:$C,">="&'Summary KPI'!$E$5) -> 0 | X10: =+SUMIFS('Data Down'!$N:$N,'Data Down'!$D:$D,'Summary KPI'!B10,'Data Down'!$R:$R,'Summary KPI'!$X$7,'Data Down'!$C:$C,"<="&'Summary KPI'!$G$5,'Data Down'!$C:$C,">="&'Summary KPI'!$E$5) -> 0 | Y10: =+SUMIFS('Data Down'!$N:$N,'Data Down'!$D:$D,'Summary KPI'!B10,'Data Down'!$R:$R,'Summary KPI'!$Y$7,'Data Down'!$C:$C,"<="&'Summary KPI'!$G$5,'Data Down'!$C:$C,">="&'Summary KPI'!$E$5) -> 7.8500126 | Z10: =+SUMIFS('Data Down'!$N:$N,'Data Down'!$D:$D,'Summary KPI'!B10,'Data Down'!$R:$R,'Summary KPI'!$Z$7,'Data Down'!$C:$C,"<="&'Summary KPI'!$G$5,'Data Down'!$C:$C,">="&'Summary KPI'!$E$5) -> 0 | AA10: =+SUMIFS('Data Down'!$N:$N,'Data Down'!$D:$D,'Summary KPI'!B10,'Data Down'!$R:$R,'Summary KPI'!$AA$7,'Data Down'!$C:$C,"<="&'Summary KPI'!$G$5,'Data Down'!$C:$C,">="&'Summary KPI'!$E$5) -> 0 | AB10: =+SUMIFS('Data Down'!$N:$N,'Data Down'!$D:$D,'Summary KPI'!B10,'Data Down'!$R:$R,'Summary KPI'!$AB$7,'Data Down'!$C:$C,"<="&'Summary KPI'!$G$5,'Data Down'!$C:$C,">="&'Summary KPI'!$E$5) -> 0 | AC10: =+SUMIFS('Data Down'!$N:$N,'Data Down'!$D:$D,'Summary KPI'!B10,'Data Down'!$R:$R,'Summary KPI'!$AC$7,'Data Down'!$C:$C,"<="&'Summary KPI'!$G$5,'Data Down'!$C:$C,">="&'Summary KPI'!$E$5) -> 0 | AD10: =(L10-AQ10)/L10 -> 0.9890972 | AE10: =+IF(F10=0,0,F10/(F10+G10+J10)) -> 0.0041666667 | AF10: =+IFERROR(F10/(F10+G10),0) -> 0.27649738 | AG10: =+F10/(F10+AQ10+J10) -> 0.0041666667 | AH10: =IF(SUM(N10:O10)=0,F10,F10/SUM(N10:O10)) -> 1 | AI10: =+IF(O10=0,F10,F10/O10) -> 1.5 | AJ10: =IFERROR(AQ10/SUM(N10:O10),0) -> 2.6166709 | AK10: =IF(M10=0,0,M10/SUM(M10:O10)) -> 0 | AL10: =IF(N10+O10+P10=0,0,(N10+P10)/(N10+O10+P10)) -> 0.33333333 | AM10: =IF(O10+N10+P10=0,0,O10/(N10+O10+P10)) -> 0.66666667 | AN10: =IF(R10+S10=0,0,R10/(R10+S10)) -> 0.11677282 | AO10: =IF(R10+S10=0,0,S10/(R10+S10)) -> 0.88322718 | AQ10: =+SUM(Q10:S10) -> 7.8500126 | AR10: =+SUM(N10:O10) -> 3 | AT10: OB x 7 Unit | AV10: 0.9 | AW10: 120 | AX10: 6
A11: =A10+1 -> 2 | B11: DT TATA 064 | C11: =VLOOKUP(B11,Sort!B:C,2,FALSE) -> Prima LX 2528 | D11: {=INDEX(HM_Unit!D:D,MATCH('Summary KPI'!B11,HM_Unit!A:A,0))} -> 16204 | E11: {=INDEX(HM_Unit!CD:CD,MATCH('Summary KPI'!B11,HM_Unit!A:A,0))} -> 16316 | F11: =E11-D11 -> 112 | G11: =SUM(R11:S11) -> 5.2666751 | H11: =Q11 -> 0 | I11: =+Z11 -> 0 | J11: =L11-F11-I11-G11-H11 -> 602.73332 | K11: =$J$5*24 -> 720 | L11: =$H$5*24 -> 720 | M11: =SUMIFS('Data Down'!U:U,'Data Down'!D:D,'Summary KPI'!B11,'Data Down'!Q:Q,'Summary KPI'!$M$8,'Data Down'!$C:$C,"<="&'Summary KPI'!$G$5,'Data Down'!$C:$C,">="&'Summary KPI'!$E$5) -> 0 | N11: =SUMIFS('Data Down'!U:U,'Data Down'!D:D,'Summary KPI'!B11,'Data Down'!Q:Q,'Summary KPI'!$N$8,'Data Down'!$C:$C,"<="&'Summary KPI'!$G$5,'Data Down'!$C:$C,">="&'Summary KPI'!$E$5) -> 0 | O11: =SUMIFS('Data Down'!U:U,'Data Down'!D:D,'Summary KPI'!B11,'Data Down'!Q:Q,'Summary KPI'!$O$8,'Data Down'!$C:$C,"<="&'Summary KPI'!$G$5,'Data Down'!$C:$C,">="&'Summary KPI'!$E$5) -> 4 | P11: =SUMIFS('Data Down'!U:U,'Data Down'!D:D,'Summary KPI'!B11,'Data Down'!Q:Q,'Summary KPI'!$P$8,'Data Down'!$C:$C,"<="&'Summary KPI'!$G$5,'Data Down'!$C:$C,">="&'Summary KPI'!$E$5) -> 0 | Q11: =SUMIFS('Data Down'!N:N,'Data Down'!$D:$D,'Summary KPI'!$B11,'Data Down'!$Q:$Q,'Summary KPI'!$Q$8,'Data Down'!$C:$C,"<="&'Summary KPI'!$G$5,'Data Down'!$C:$C,">="&'Summary KPI'!$E$5) -> 0 | R11: =SUMIFS('Data Down'!N:N,'Data Down'!D:D,'Summary KPI'!B11,'Data Down'!Q:Q,'Summary KPI'!$R$8,'Data Down'!$C:$C,"<="&'Summary KPI'!$G$5,'Data Down'!$C:$C,">="&'Summary KPI'!$E$5) -> 0 | S11: =SUMIFS('Data Down'!N:N,'Data Down'!D:D,'Summary KPI'!B11,'Data Down'!Q:Q,'Summary KPI'!$S$8,'Data Down'!$C:$C,"<="&'Summary KPI'!$G$5,'Data Down'!$C:$C,">="&'Summary KPI'!$E$5) -> 5.2666751 | T11: =SUMIFS('Data Down'!N:N,'Data Down'!D:D,'Summary KPI'!B11,'Data Down'!Q:Q,'Summary KPI'!$T$8,'Data Down'!$C:$C,"<="&'Summary KPI'!$G$5,'Data Down'!$C:$C,">="&'Summary KPI'!$E$5) -> 0 | U11: =+SUMIFS('Data Down'!$N:$N,'Data Down'!$D:$D,'Summary KPI'!B11,'Data Down'!$R:$R,'Summary KPI'!$U$7,'Data Down'!$C:$C,"<="&'Summary KPI'!$G$5,'Data Down'!$C:$C,">="&'Summary KPI'!$E$5) -> 0 | V11: =+SUMIFS('Data Down'!$N:$N,'Data Down'!$D:$D,'Summary KPI'!B11,'Data Down'!$R:$R,'Summary KPI'!$V$7,'Data Down'!$C:$C,"<="&'Summary KPI'!$G$5,'Data Down'!$C:$C,">="&'Summary KPI'!$E$5) -> 0 | W11: =+SUMIFS('Data Down'!$N:$N,'Data Down'!$D:$D,'Summary KPI'!B11,'Data Down'!$R:$R,'Summary KPI'!$W$7,'Data Down'!$C:$C,"<="&'Summary KPI'!$G$5,'Data Down'!$C:$C,">="&'Summary KPI'!$E$5) -> 0 | X11: =+SUMIFS('Data Down'!$N:$N,'Data Down'!$D:$D,'Summary KPI'!B11,'Data Down'!$R:$R,'Summary KPI'!$X$7,'Data Down'!$C:$C,"<="&'Summary KPI'!$G$5,'Data Down'!$C:$C,">="&'Summary KPI'!$E$5) -> 0 | Y11: =+SUMIFS('Data Down'!$N:$N,'Data Down'!$D:$D,'Summary KPI'!B11,'Data Down'!$R:$R,'Summary KPI'!$Y$7,'Data Down'!$C:$C,"<="&'Summary KPI'!$G$5,'Data Down'!$C:$C,">="&'Summary KPI'!$E$5) -> 5.2666751 | Z11: =+SUMIFS('Data Down'!$N:$N,'Data Down'!$D:$D,'Summary KPI'!B11,'Data Down'!$R:$R,'Summary KPI'!$Z$7,'Data Down'!$C:$C,"<="&'Summary KPI'!$G$5,'Data Down'!$C:$C,">="&'Summary KPI'!$E$5) -> 0 | AA11: =+SUMIFS('Data Down'!$N:$N,'Data Down'!$D:$D,'Summary KPI'!B11,'Data Down'!$R:$R,'Summary KPI'!$AA$7,'Data Down'!$C:$C,"<="&'Summary KPI'!$G$5,'Data Down'!$C:$C,">="&'Summary KPI'!$E$5) -> 0 | AB11: =+SUMIFS('Data Down'!$N:$N,'Data Down'!$D:$D,'Summary KPI'!B11,'Data Down'!$R:$R,'Summary KPI'!$AB$7,'Data Down'!$C:$C,"<="&'Summary KPI'!$G$5,'Data Down'!$C:$C,">="&'Summary KPI'!$E$5) -> 0 | AC11: =+SUMIFS('Data Down'!$N:$N,'Data Down'!$D:$D,'Summary KPI'!B11,'Data Down'!$R:$R,'Summary KPI'!$AC$7,'Data Down'!$C:$C,"<="&'Summary KPI'!$G$5,'Data Down'!$C:$C,">="&'Summary KPI'!$E$5) -> 0 | AD11: =(L11-AQ11)/L11 -> 0.99268517 | AE11: =+IF(F11=0,0,F11/(F11+G11+J11)) -> 0.15555556 | AF11: =+IFERROR(F11/(F11+G11),0) -> 0.95508805 | AG11: =+F11/(F11+AQ11+J11) -> 0.15555556 | AH11: =IF(SUM(N11:O11)=0,F11,F11/SUM(N11:O11)) -> 28 | AI11: =+IF(O11=0,F11,F11/O11) -> 28 | AJ11: =IFERROR(AQ11/SUM(N11:O11),0) -> 1.3166688 | AK11: =IF(M11=0,0,M11/SUM(M11:O11)) -> 0 | AL11: =IF(N11+O11+P11=0,0,(N11+P11)/(N11+O11+P11)) -> 0 | AM11: =IF(O11+N11+P11=0,0,O11/(N11+O11+P11)) -> 1 | AN11: =IF(R11+S11=0,0,R11/(R11+S11)) -> 0 | AO11: =IF(R11+S11=0,0,S11/(R11+S11)) -> 1 | AQ11: =+SUM(Q11:S11) -> 5.2666751 | AR11: =+SUM(N11:O11) -> 4 | AT11: OB x 7 Unit | AV11: 0.9 | AW11: 120 | AX11: 6
A12: =A11+1 -> 3 | B12: DT TATA 070 | C12: =VLOOKUP(B12,Sort!B:C,2,FALSE) -> Prima LX 2528 | D12: {=INDEX(HM_Unit!D:D,MATCH('Summary KPI'!B12,HM_Unit!A:A,0))} -> 13239 | E12: {=INDEX(HM_Unit!CD:CD,MATCH('Summary KPI'!B12,HM_Unit!A:A,0))} -> 13404 | F12: =E12-D12 -> 165 | G12: =SUM(R12:S12) -> 17.583361 | H12: =Q12 -> 0 | I12: =+Z12 -> 0 | J12: =L12-F12-I12-G12-H12 -> 537.41664 | K12: =$J$5*24 -> 720 | L12: =$H$5*24 -> 720 | M12: =SUMIFS('Data Down'!U:U,'Data Down'!D:D,'Summary KPI'!B12,'Data Down'!Q:Q,'Summary KPI'!$M$8,'Data Down'!$C:$C,"<="&'Summary KPI'!$G$5,'Data Down'!$C:$C,">="&'Summary KPI'!$E$5) -> 0 | N12: =SUMIFS('Data Down'!U:U,'Data Down'!D:D,'Summary KPI'!B12,'Data Down'!Q:Q,'Summary KPI'!$N$8,'Data Down'!$C:$C,"<="&'Summary KPI'!$G$5,'Data Down'!$C:$C,">="&'Summary KPI'!$E$5) -> 1 | O12: =SUMIFS('Data Down'!U:U,'Data Down'!D:D,'Summary KPI'!B12,'Data Down'!Q:Q,'Summary KPI'!$O$8,'Data Down'!$C:$C,"<="&'Summary KPI'!$G$5,'Data Down'!$C:$C,">="&'Summary KPI'!$E$5) -> 3 | P12: =SUMIFS('Data Down'!U:U,'Data Down'!D:D,'Summary KPI'!B12,'Data Down'!Q:Q,'Summary KPI'!$P$8,'Data Down'!$C:$C,"<="&'Summary KPI'!$G$5,'Data Down'!$C:$C,">="&'Summary KPI'!$E$5) -> 0 | Q12: =SUMIFS('Data Down'!N:N,'Data Down'!$D:$D,'Summary KPI'!$B12,'Data Down'!$Q:$Q,'Summary KPI'!$Q$8,'Data Down'!$C:$C,"<="&'Summary KPI'!$G$5,'Data Down'!$C:$C,">="&'Summary KPI'!$E$5) -> 0 | R12: =SUMIFS('Data Down'!N:N,'Data Down'!D:D,'Summary KPI'!B12,'Data Down'!Q:Q,'Summary KPI'!$R$8,'Data Down'!$C:$C,"<="&'Summary KPI'!$G$5,'Data Down'!$C:$C,">="&'Summary KPI'!$E$5) -> 1.1166685 | S12: =SUMIFS('Data Down'!N:N,'Data Down'!D:D,'Summary KPI'!B12,'Data Down'!Q:Q,'Summary KPI'!$S$8,'Data Down'!$C:$C,"<="&'Summary KPI'!$G$5,'Data Down'!$C:$C,">="&'Summary KPI'!$E$5) -> 16.466693 | T12: =SUMIFS('Data Down'!N:N,'Data Down'!D:D,'Summary KPI'!B12,'Data Down'!Q:Q,'Summary KPI'!$T$8,'Data Down'!$C:$C,"<="&'Summary KPI'!$G$5,'Data Down'!$C:$C,">="&'Summary KPI'!$E$5) -> 0 | U12: =+SUMIFS('Data Down'!$N:$N,'Data Down'!$D:$D,'Summary KPI'!B12,'Data Down'!$R:$R,'Summary KPI'!$U$7,'Data Down'!$C:$C,"<="&'Summary KPI'!$G$5,'Data Down'!$C:$C,">="&'Summary KPI'!$E$5) -> 0 | V12: =+SUMIFS('Data Down'!$N:$N,'Data Down'!$D:$D,'Summary KPI'!B12,'Data Down'!$R:$R,'Summary KPI'!$V$7,'Data Down'!$C:$C,"<="&'Summary KPI'!$G$5,'Data Down'!$C:$C,">="&'Summary KPI'!$E$5) -> 0 | W12: =+SUMIFS('Data Down'!$N:$N,'Data Down'!$D:$D,'Summary KPI'!B12,'Data Down'!$R:$R,'Summary KPI'!$W$7,'Data Down'!$C:$C,"<="&'Summary KPI'!$G$5,'Data Down'!$C:$C,">="&'Summary KPI'!$E$5) -> 0 | X12: =+SUMIFS('Data Down'!$N:$N,'Data Down'!$D:$D,'Summary KPI'!B12,'Data Down'!$R:$R,'Summary KPI'!$X$7,'Data Down'!$C:$C,"<="&'Summary KPI'!$G$5,'Data Down'!$C:$C,">="&'Summary KPI'!$E$5) -> 0 | Y12: =+SUMIFS('Data Down'!$N:$N,'Data Down'!$D:$D,'Summary KPI'!B12,'Data Down'!$R:$R,'Summary KPI'!$Y$7,'Data Down'!$C:$C,"<="&'Summary KPI'!$G$5,'Data Down'!$C:$C,">="&'Summary KPI'!$E$5) -> 17.583361 | Z12: =+SUMIFS('Data Down'!$N:$N,'Data Down'!$D:$D,'Summary KPI'!B12,'Data Down'!$R:$R,'Summary KPI'!$Z$7,'Data Down'!$C:$C,"<="&'Summary KPI'!$G$5,'Data Down'!$C:$C,">="&'Summary KPI'!$E$5) -> 0 | AA12: =+SUMIFS('Data Down'!$N:$N,'Data Down'!$D:$D,'Summary KPI'!B12,'Data Down'!$R:$R,'Summary KPI'!$AA$7,'Data Down'!$C:$C,"<="&'Summary KPI'!$G$5,'Data Down'!$C:$C,">="&'Summary KPI'!$E$5) -> 0 | AB12: =+SUMIFS('Data Down'!$N:$N,'Data Down'!$D:$D,'Summary KPI'!B12,'Data Down'!$R:$R,'Summary KPI'!$AB$7,'Data Down'!$C:$C,"<="&'Summary KPI'!$G$5,'Data Down'!$C:$C,">="&'Summary KPI'!$E$5) -> 0 | AC12: =+SUMIFS('Data Down'!$N:$N,'Data Down'!$D:$D,'Summary KPI'!B12,'Data Down'!$R:$R,'Summary KPI'!$AC$7,'Data Down'!$C:$C,"<="&'Summary KPI'!$G$5,'Data Down'!$C:$C,">="&'Summary KPI'!$E$5) -> 0 | AD12: =(L12-AQ12)/L12 -> 0.97557866 | AE12: =+IF(F12=0,0,F12/(F12+G12+J12)) -> 0.22916667 | AF12: =+IFERROR(F12/(F12+G12),0) -> 0.9036968 | AG12: =+F12/(F12+AQ12+J12) -> 0.22916667 | AH12: =IF(SUM(N12:O12)=0,F12,F12/SUM(N12:O12)) -> 41.25 | AI12: =+IF(O12=0,F12,F12/O12) -> 55 | AJ12: =IFERROR(AQ12/SUM(N12:O12),0) -> 4.3958404 | AK12: =IF(M12=0,0,M12/SUM(M12:O12)) -> 0 | AL12: =IF(N12+O12+P12=0,0,(N12+P12)/(N12+O12+P12)) -> 0.25 | AM12: =IF(O12+N12+P12=0,0,O12/(N12+O12+P12)) -> 0.75 | AN12: =IF(R12+S12=0,0,R12/(R12+S12)) -> 0.063507109 | AO12: =IF(R12+S12=0,0,S12/(R12+S12)) -> 0.93649289 | AQ12: =+SUM(Q12:S12) -> 17.583361 | AR12: =+SUM(N12:O12) -> 4 | AT12: OB x 7 Unit | AV12: 0.9 | AW12: 120 | AX12: 6
A13: =A12+1 -> 4 | B13: DT TATA 078 | C13: =VLOOKUP(B13,Sort!B:C,2,FALSE) -> Prima LX 2528 | D13: {=INDEX(HM_Unit!D:D,MATCH('Summary KPI'!B13,HM_Unit!A:A,0))} -> 13225 | E13: {=INDEX(HM_Unit!CD:CD,MATCH('Summary KPI'!B13,HM_Unit!A:A,0))} -> 13385 | F13: =E13-D13 -> 160 | G13: =SUM(R13:S13) -> 5.9500095 | H13: =Q13 -> 0 | I13: =+Z13 -> 0 | J13: =L13-F13-I13-G13-H13 -> 554.04999 | K13: =$J$5*24 -> 720 | L13: =$H$5*24 -> 720 | M13: =SUMIFS('Data Down'!U:U,'Data Down'!D:D,'Summary KPI'!B13,'Data Down'!Q:Q,'Summary KPI'!$M$8,'Data Down'!$C:$C,"<="&'Summary KPI'!$G$5,'Data Down'!$C:$C,">="&'Summary KPI'!$E$5) -> 0 | N13: =SUMIFS('Data Down'!U:U,'Data Down'!D:D,'Summary KPI'!B13,'Data Down'!Q:Q,'Summary KPI'!$N$8,'Data Down'!$C:$C,"<="&'Summary KPI'!$G$5,'Data Down'!$C:$C,">="&'Summary KPI'!$E$5) -> 1 | O13: =SUMIFS('Data Down'!U:U,'Data Down'!D:D,'Summary KPI'!B13,'Data Down'!Q:Q,'Summary KPI'!$O$8,'Data Down'!$C:$C,"<="&'Summary KPI'!$G$5,'Data Down'!$C:$C,">="&'Summary KPI'!$E$5) -> 5 | P13: =SUMIFS('Data Down'!U:U,'Data Down'!D:D,'Summary KPI'!B13,'Data Down'!Q:Q,'Summary KPI'!$P$8,'Data Down'!$C:$C,"<="&'Summary KPI'!$G$5,'Data Down'!$C:$C,">="&'Summary KPI'!$E$5) -> 0 | Q13: =SUMIFS('Data Down'!N:N,'Data Down'!$D:$D,'Summary KPI'!$B13,'Data Down'!$Q:$Q,'Summary KPI'!$Q$8,'Data Down'!$C:$C,"<="&'Summary KPI'!$G$5,'Data Down'!$C:$C,">="&'Summary KPI'!$E$5) -> 0 | R13: =SUMIFS('Data Down'!N:N,'Data Down'!D:D,'Summary KPI'!B13,'Data Down'!Q:Q,'Summary KPI'!$R$8,'Data Down'!$C:$C,"<="&'Summary KPI'!$G$5,'Data Down'!$C:$C,">="&'Summary KPI'!$E$5) -> 3.0333382 | S13: =SUMIFS('Data Down'!N:N,'Data Down'!D:D,'Summary KPI'!B13,'Data Down'!Q:Q,'Summary KPI'!$S$8,'Data Down'!$C:$C,"<="&'Summary KPI'!$G$5,'Data Down'!$C:$C,">="&'Summary KPI'!$E$5) -> 2.9166713 | T13: =SUMIFS('Data Down'!N:N,'Data Down'!D:D,'Summary KPI'!B13,'Data Down'!Q:Q,'Summary KPI'!$T$8,'Data Down'!$C:$C,"<="&'Summary KPI'!$G$5,'Data Down'!$C:$C,">="&'Summary KPI'!$E$5) -> 0 | U13: =+SUMIFS('Data Down'!$N:$N,'Data Down'!$D:$D,'Summary KPI'!B13,'Data Down'!$R:$R,'Summary KPI'!$U$7,'Data Down'!$C:$C,"<="&'Summary KPI'!$G$5,'Data Down'!$C:$C,">="&'Summary KPI'!$E$5) -> 0 | V13: =+SUMIFS('Data Down'!$N:$N,'Data Down'!$D:$D,'Summary KPI'!B13,'Data Down'!$R:$R,'Summary KPI'!$V$7,'Data Down'!$C:$C,"<="&'Summary KPI'!$G$5,'Data Down'!$C:$C,">="&'Summary KPI'!$E$5) -> 0 | W13: =+SUMIFS('Data Down'!$N:$N,'Data Down'!$D:$D,'Summary KPI'!B13,'Data Down'!$R:$R,'Summary KPI'!$W$7,'Data Down'!$C:$C,"<="&'Summary KPI'!$G$5,'Data Down'!$C:$C,">="&'Summary KPI'!$E$5) -> 0 | X13: =+SUMIFS('Data Down'!$N:$N,'Data Down'!$D:$D,'Summary KPI'!B13,'Data Down'!$R:$R,'Summary KPI'!$X$7,'Data Down'!$C:$C,"<="&'Summary KPI'!$G$5,'Data Down'!$C:$C,">="&'Summary KPI'!$E$5) -> 0 | Y13: =+SUMIFS('Data Down'!$N:$N,'Data Down'!$D:$D,'Summary KPI'!B13,'Data Down'!$R:$R,'Summary KPI'!$Y$7,'Data Down'!$C:$C,"<="&'Summary KPI'!$G$5,'Data Down'!$C:$C,">="&'Summary KPI'!$E$5) -> 5.9500095 | Z13: =+SUMIFS('Data Down'!$N:$N,'Data Down'!$D:$D,'Summary KPI'!B13,'Data Down'!$R:$R,'Summary KPI'!$Z$7,'Data Down'!$C:$C,"<="&'Summary KPI'!$G$5,'Data Down'!$C:$C,">="&'Summary KPI'!$E$5) -> 0 | AA13: =+SUMIFS('Data Down'!$N:$N,'Data Down'!$D:$D,'Summary KPI'!B13,'Data Down'!$R:$R,'Summary KPI'!$AA$7,'Data Down'!$C:$C,"<="&'Summary KPI'!$G$5,'Data Down'!$C:$C,">="&'Summary KPI'!$E$5) -> 0 | AB13: =+SUMIFS('Data Down'!$N:$N,'Data Down'!$D:$D,'Summary KPI'!B13,'Data Down'!$R:$R,'Summary KPI'!$AB$7,'Data Down'!$C:$C,"<="&'Summary KPI'!$G$5,'Data Down'!$C:$C,">="&'Summary KPI'!$E$5) -> 0 | AC13: =+SUMIFS('Data Down'!$N:$N,'Data Down'!$D:$D,'Summary KPI'!B13,'Data Down'!$R:$R,'Summary KPI'!$AC$7,'Data Down'!$C:$C,"<="&'Summary KPI'!$G$5,'Data Down'!$C:$C,">="&'Summary KPI'!$E$5) -> 0 | AD13: =(L13-AQ13)/L13 -> 0.9917361 | AE13: =+IF(F13=0,0,F13/(F13+G13+J13)) -> 0.22222222 | AF13: =+IFERROR(F13/(F13+G13),0) -> 0.96414577 | AG13: =+F13/(F13+AQ13+J13) -> 0.22222222 | AH13: =IF(SUM(N13:O13)=0,F13,F13/SUM(N13:O13)) -> 26.666667 | AI13: =+IF(O13=0,F13,F13/O13) -> 32 | AJ13: =IFERROR(AQ13/SUM(N13:O13),0) -> 0.99166825 | AK13: =IF(M13=0,0,M13/SUM(M13:O13)) -> 0 | AL13: =IF(N13+O13+P13=0,0,(N13+P13)/(N13+O13+P13)) -> 0.16666667 | AM13: =IF(O13+N13+P13=0,0,O13/(N13+O13+P13)) -> 0.83333333 | AN13: =IF(R13+S13=0,0,R13/(R13+S13)) -> 0.50980392 | AO13: =IF(R13+S13=0,0,S13/(R13+S13)) -> 0.49019608 | AQ13: =+SUM(Q13:S13) -> 5.9500095 | AR13: =+SUM(N13:O13) -> 6 | AT13: OB x 7 Unit | AV13: 0.9 | AW13: 120 | AX13: 6
A14: =A13+1 -> 5 | B14: DT TATA 085 | C14: =VLOOKUP(B14,Sort!B:C,2,FALSE) -> Prima LX 2528 | D14: {=INDEX(HM_Unit!D:D,MATCH('Summary KPI'!B14,HM_Unit!A:A,0))} -> 15461 | E14: {=INDEX(HM_Unit!CD:CD,MATCH('Summary KPI'!B14,HM_Unit!A:A,0))} -> 15612 | F14: =E14-D14 -> 151 | G14: =SUM(R14:S14) -> 4.1333399 | H14: =Q14 -> 0 | I14: =+Z14 -> 0 | J14: =L14-F14-I14-G14-H14 -> 564.86666 | K14: =$J$5*24 -> 720 | L14: =$H$5*24 -> 720 | M14: =SUMIFS('Data Down'!U:U,'Data Down'!D:D,'Summary KPI'!B14,'Data Down'!Q:Q,'Summary KPI'!$M$8,'Data Down'!$C:$C,"<="&'Summary KPI'!$G$5,'Data Down'!$C:$C,">="&'Summary KPI'!$E$5) -> 0 | N14: =SUMIFS('Data Down'!U:U,'Data Down'!D:D,'Summary KPI'!B14,'Data Down'!Q:Q,'Summary KPI'!$N$8,'Data Down'!$C:$C,"<="&'Summary KPI'!$G$5,'Data Down'!$C:$C,">="&'Summary KPI'!$E$5) -> 0 | O14: =SUMIFS('Data Down'!U:U,'Data Down'!D:D,'Summary KPI'!B14,'Data Down'!Q:Q,'Summary KPI'!$O$8,'Data Down'!$C:$C,"<="&'Summary KPI'!$G$5,'Data Down'!$C:$C,">="&'Summary KPI'!$E$5) -> 2 | P14: =SUMIFS('Data Down'!U:U,'Data Down'!D:D,'Summary KPI'!B14,'Data Down'!Q:Q,'Summary KPI'!$P$8,'Data Down'!$C:$C,"<="&'Summary KPI'!$G$5,'Data Down'!$C:$C,">="&'Summary KPI'!$E$5) -> 0 | Q14: =SUMIFS('Data Down'!N:N,'Data Down'!$D:$D,'Summary KPI'!$B14,'Data Down'!$Q:$Q,'Summary KPI'!$Q$8,'Data Down'!$C:$C,"<="&'Summary KPI'!$G$5,'Data Down'!$C:$C,">="&'Summary KPI'!$E$5) -> 0 | R14: =SUMIFS('Data Down'!N:N,'Data Down'!D:D,'Summary KPI'!B14,'Data Down'!Q:Q,'Summary KPI'!$R$8,'Data Down'!$C:$C,"<="&'Summary KPI'!$G$5,'Data Down'!$C:$C,">="&'Summary KPI'!$E$5) -> 0 | S14: =SUMIFS('Data Down'!N:N,'Data Down'!D:D,'Summary KPI'!B14,'Data Down'!Q:Q,'Summary KPI'!$S$8,'Data Down'!$C:$C,"<="&'Summary KPI'!$G$5,'Data Down'!$C:$C,">="&'Summary KPI'!$E$5) -> 4.1333399 | T14: =SUMIFS('Data Down'!N:N,'Data Down'!D:D,'Summary KPI'!B14,'Data Down'!Q:Q,'Summary KPI'!$T$8,'Data Down'!$C:$C,"<="&'Summary KPI'!$G$5,'Data Down'!$C:$C,">="&'Summary KPI'!$E$5) -> 0 | U14: =+SUMIFS('Data Down'!$N:$N,'Data Down'!$D:$D,'Summary KPI'!B14,'Data Down'!$R:$R,'Summary KPI'!$U$7,'Data Down'!$C:$C,"<="&'Summary KPI'!$G$5,'Data Down'!$C:$C,">="&'Summary KPI'!$E$5) -> 0 | V14: =+SUMIFS('Data Down'!$N:$N,'Data Down'!$D:$D,'Summary KPI'!B14,'Data Down'!$R:$R,'Summary KPI'!$V$7,'Data Down'!$C:$C,"<="&'Summary KPI'!$G$5,'Data Down'!$C:$C,">="&'Summary KPI'!$E$5) -> 0 | W14: =+SUMIFS('Data Down'!$N:$N,'Data Down'!$D:$D,'Summary KPI'!B14,'Data Down'!$R:$R,'Summary KPI'!$W$7,'Data Down'!$C:$C,"<="&'Summary KPI'!$G$5,'Data Down'!$C:$C,">="&'Summary KPI'!$E$5) -> 0 | X14: =+SUMIFS('Data Down'!$N:$N,'Data Down'!$D:$D,'Summary KPI'!B14,'Data Down'!$R:$R,'Summary KPI'!$X$7,'Data Down'!$C:$C,"<="&'Summary KPI'!$G$5,'Data Down'!$C:$C,">="&'Summary KPI'!$E$5) -> 0 | Y14: =+SUMIFS('Data Down'!$N:$N,'Data Down'!$D:$D,'Summary KPI'!B14,'Data Down'!$R:$R,'Summary KPI'!$Y$7,'Data Down'!$C:$C,"<="&'Summary KPI'!$G$5,'Data Down'!$C:$C,">="&'Summary KPI'!$E$5) -> 4.1333399 | Z14: =+SUMIFS('Data Down'!$N:$N,'Data Down'!$D:$D,'Summary KPI'!B14,'Data Down'!$R:$R,'Summary KPI'!$Z$7,'Data Down'!$C:$C,"<="&'Summary KPI'!$G$5,'Data Down'!$C:$C,">="&'Summary KPI'!$E$5) -> 0 | AA14: =+SUMIFS('Data Down'!$N:$N,'Data Down'!$D:$D,'Summary KPI'!B14,'Data Down'!$R:$R,'Summary KPI'!$AA$7,'Data Down'!$C:$C,"<="&'Summary KPI'!$G$5,'Data Down'!$C:$C,">="&'Summary KPI'!$E$5) -> 0 | AB14: =+SUMIFS('Data Down'!$N:$N,'Data Down'!$D:$D,'Summary KPI'!B14,'Data Down'!$R:$R,'Summary KPI'!$AB$7,'Data Down'!$C:$C,"<="&'Summary KPI'!$G$5,'Data Down'!$C:$C,">="&'Summary KPI'!$E$5) -> 0 | AC14: =+SUMIFS('Data Down'!$N:$N,'Data Down'!$D:$D,'Summary KPI'!B14,'Data Down'!$R:$R,'Summary KPI'!$AC$7,'Data Down'!$C:$C,"<="&'Summary KPI'!$G$5,'Data Down'!$C:$C,">="&'Summary KPI'!$E$5) -> 0 | AD14: =(L14-AQ14)/L14 -> 0.99425925 | AE14: =+IF(F14=0,0,F14/(F14+G14+J14)) -> 0.20972222 | AF14: =+IFERROR(F14/(F14+G14),0) -> 0.97335621 | AG14: =+F14/(F14+AQ14+J14) -> 0.20972222 | AH14: =IF(SUM(N14:O14)=0,F14,F14/SUM(N14:O14)) -> 75.5 | AI14: =+IF(O14=0,F14,F14/O14) -> 75.5 | AJ14: =IFERROR(AQ14/SUM(N14:O14),0) -> 2.06667 | AK14: =IF(M14=0,0,M14/SUM(M14:O14)) -> 0 | AL14: =IF(N14+O14+P14=0,0,(N14+P14)/(N14+O14+P14)) -> 0 | AM14: =IF(O14+N14+P14=0,0,O14/(N14+O14+P14)) -> 1 | AN14: =IF(R14+S14=0,0,R14/(R14+S14)) -> 0 | AO14: =IF(R14+S14=0,0,S14/(R14+S14)) -> 1 | AQ14: =+SUM(Q14:S14) -> 4.1333399 | AR14: =+SUM(N14:O14) -> 2 | AT14: OB x 7 Unit | AV14: 0.9 | AW14: 120 | AX14: 6
A15: =A14+1 -> 6 | B15: DT TATA 086 | C15: =VLOOKUP(B15,Sort!B:C,2,FALSE) -> Prima LX 2528 | D15: {=INDEX(HM_Unit!D:D,MATCH('Summary KPI'!B15,HM_Unit!A:A,0))} -> 15411 | E15: {=INDEX(HM_Unit!CD:CD,MATCH('Summary KPI'!B15,HM_Unit!A:A,0))} -> 15433 | F15: =E15-D15 -> 22 | G15: =SUM(R15:S15) -> 6.9500111 | H15: =Q15 -> 0 | I15: =+Z15 -> 0 | J15: =L15-F15-I15-G15-H15 -> 691.04999 | K15: =$J$5*24 -> 720 | L15: =$H$5*24 -> 720 | M15: =SUMIFS('Data Down'!U:U,'Data Down'!D:D,'Summary KPI'!B15,'Data Down'!Q:Q,'Summary KPI'!$M$8,'Data Down'!$C:$C,"<="&'Summary KPI'!$G$5,'Data Down'!$C:$C,">="&'Summary KPI'!$E$5) -> 0 | N15: =SUMIFS('Data Down'!U:U,'Data Down'!D:D,'Summary KPI'!B15,'Data Down'!Q:Q,'Summary KPI'!$N$8,'Data Down'!$C:$C,"<="&'Summary KPI'!$G$5,'Data Down'!$C:$C,">="&'Summary KPI'!$E$5) -> 1 | O15: =SUMIFS('Data Down'!U:U,'Data Down'!D:D,'Summary KPI'!B15,'Data Down'!Q:Q,'Summary KPI'!$O$8,'Data Down'!$C:$C,"<="&'Summary KPI'!$G$5,'Data Down'!$C:$C,">="&'Summary KPI'!$E$5) -> 3 | P15: =SUMIFS('Data Down'!U:U,'Data Down'!D:D,'Summary KPI'!B15,'Data Down'!Q:Q,'Summary KPI'!$P$8,'Data Down'!$C:$C,"<="&'Summary KPI'!$G$5,'Data Down'!$C:$C,">="&'Summary KPI'!$E$5) -> 0 | Q15: =SUMIFS('Data Down'!N:N,'Data Down'!$D:$D,'Summary KPI'!$B15,'Data Down'!$Q:$Q,'Summary KPI'!$Q$8,'Data Down'!$C:$C,"<="&'Summary KPI'!$G$5,'Data Down'!$C:$C,">="&'Summary KPI'!$E$5) -> 0 | R15: =SUMIFS('Data Down'!N:N,'Data Down'!D:D,'Summary KPI'!B15,'Data Down'!Q:Q,'Summary KPI'!$R$8,'Data Down'!$C:$C,"<="&'Summary KPI'!$G$5,'Data Down'!$C:$C,">="&'Summary KPI'!$E$5) -> 0.41666733 | S15: =SUMIFS('Data Down'!N:N,'Data Down'!D:D,'Summary KPI'!B15,'Data Down'!Q:Q,'Summary KPI'!$S$8,'Data Down'!$C:$C,"<="&'Summary KPI'!$G$5,'Data Down'!$C:$C,">="&'Summary KPI'!$E$5) -> 6.5333438 | T15: =SUMIFS('Data Down'!N:N,'Data Down'!D:D,'Summary KPI'!B15,'Data Down'!Q:Q,'Summary KPI'!$T$8,'Data Down'!$C:$C,"<="&'Summary KPI'!$G$5,'Data Down'!$C:$C,">="&'Summary KPI'!$E$5) -> 0 | U15: =+SUMIFS('Data Down'!$N:$N,'Data Down'!$D:$D,'Summary KPI'!B15,'Data Down'!$R:$R,'Summary KPI'!$U$7,'Data Down'!$C:$C,"<="&'Summary KPI'!$G$5,'Data Down'!$C:$C,">="&'Summary KPI'!$E$5) -> 0 | V15: =+SUMIFS('Data Down'!$N:$N,'Data Down'!$D:$D,'Summary KPI'!B15,'Data Down'!$R:$R,'Summary KPI'!$V$7,'Data Down'!$C:$C,"<="&'Summary KPI'!$G$5,'Data Down'!$C:$C,">="&'Summary KPI'!$E$5) -> 0 | W15: =+SUMIFS('Data Down'!$N:$N,'Data Down'!$D:$D,'Summary KPI'!B15,'Data Down'!$R:$R,'Summary KPI'!$W$7,'Data Down'!$C:$C,"<="&'Summary KPI'!$G$5,'Data Down'!$C:$C,">="&'Summary KPI'!$E$5) -> 0 | X15: =+SUMIFS('Data Down'!$N:$N,'Data Down'!$D:$D,'Summary KPI'!B15,'Data Down'!$R:$R,'Summary KPI'!$X$7,'Data Down'!$C:$C,"<="&'Summary KPI'!$G$5,'Data Down'!$C:$C,">="&'Summary KPI'!$E$5) -> 0 | Y15: =+SUMIFS('Data Down'!$N:$N,'Data Down'!$D:$D,'Summary KPI'!B15,'Data Down'!$R:$R,'Summary KPI'!$Y$7,'Data Down'!$C:$C,"<="&'Summary KPI'!$G$5,'Data Down'!$C:$C,">="&'Summary KPI'!$E$5) -> 6.9500111 | Z15: =+SUMIFS('Data Down'!$N:$N,'Data Down'!$D:$D,'Summary KPI'!B15,'Data Down'!$R:$R,'Summary KPI'!$Z$7,'Data Down'!$C:$C,"<="&'Summary KPI'!$G$5,'Data Down'!$C:$C,">="&'Summary KPI'!$E$5) -> 0 | AA15: =+SUMIFS('Data Down'!$N:$N,'Data Down'!$D:$D,'Summary KPI'!B15,'Data Down'!$R:$R,'Summary KPI'!$AA$7,'Data Down'!$C:$C,"<="&'Summary KPI'!$G$5,'Data Down'!$C:$C,">="&'Summary KPI'!$E$5) -> 0 | AB15: =+SUMIFS('Data Down'!$N:$N,'Data Down'!$D:$D,'Summary KPI'!B15,'Data Down'!$R:$R,'Summary KPI'!$AB$7,'Data Down'!$C:$C,"<="&'Summary KPI'!$G$5,'Data Down'!$C:$C,">="&'Summary KPI'!$E$5) -> 0 | AC15: =+SUMIFS('Data Down'!$N:$N,'Data Down'!$D:$D,'Summary KPI'!B15,'Data Down'!$R:$R,'Summary KPI'!$AC$7,'Data Down'!$C:$C,"<="&'Summary KPI'!$G$5,'Data Down'!$C:$C,">="&'Summary KPI'!$E$5) -> 0 | AD15: =(L15-AQ15)/L15 -> 0.99034721 | AE15: =+IF(F15=0,0,F15/(F15+G15+J15)) -> 0.030555556 | AF15: =+IFERROR(F15/(F15+G15),0) -> 0.75993062 | AG15: =+F15/(F15+AQ15+J15) -> 0.030555556 | AH15: =IF(SUM(N15:O15)=0,F15,F15/SUM(N15:O15)) -> 5.5 | AI15: =+IF(O15=0,F15,F15/O15) -> 7.3333333 | AJ15: =IFERROR(AQ15/SUM(N15:O15),0) -> 1.7375028 | AK15: =IF(M15=0,0,M15/SUM(M15:O15)) -> 0 | AL15: =IF(N15+O15+P15=0,0,(N15+P15)/(N15+O15+P15)) -> 0.25 | AM15: =IF(O15+N15+P15=0,0,O15/(N15+O15+P15)) -> 0.75 | AN15: =IF(R15+S15=0,0,R15/(R15+S15)) -> 0.059952038 | AO15: =IF(R15+S15=0,0,S15/(R15+S15)) -> 0.94004796 | AQ15: =+SUM(Q15:S15) -> 6.9500111 | AR15: =+SUM(N15:O15) -> 4 | AT15: OB x 7 Unit | AV15: 0.9 | AW15: 120 | AX15: 6
A16: =A15+1 -> 7 | B16: DT TATA 088 | C16: =VLOOKUP(B16,Sort!B:C,2,FALSE) -> Prima LX 2528 | D16: {=INDEX(HM_Unit!D:D,MATCH('Summary KPI'!B16,HM_Unit!A:A,0))} -> 15743 | E16: {=INDEX(HM_Unit!CD:CD,MATCH('Summary KPI'!B16,HM_Unit!A:A,0))} -> 15797 | F16: =E16-D16 -> 54 | G16: =SUM(R16:S16) -> 13.416688 | H16: =Q16 -> 0 | I16: =+Z16 -> 0 | J16: =L16-F16-I16-G16-H16 -> 652.58331 | K16: =$J$5*24 -> 720 | L16: =$H$5*24 -> 720 | M16: =SUMIFS('Data Down'!U:U,'Data Down'!D:D,'Summary KPI'!B16,'Data Down'!Q:Q,'Summary KPI'!$M$8,'Data Down'!$C:$C,"<="&'Summary KPI'!$G$5,'Data Down'!$C:$C,">="&'Summary KPI'!$E$5) -> 0 | N16: =SUMIFS('Data Down'!U:U,'Data Down'!D:D,'Summary KPI'!B16,'Data Down'!Q:Q,'Summary KPI'!$N$8,'Data Down'!$C:$C,"<="&'Summary KPI'!$G$5,'Data Down'!$C:$C,">="&'Summary KPI'!$E$5) -> 0 | O16: =SUMIFS('Data Down'!U:U,'Data Down'!D:D,'Summary KPI'!B16,'Data Down'!Q:Q,'Summary KPI'!$O$8,'Data Down'!$C:$C,"<="&'Summary KPI'!$G$5,'Data Down'!$C:$C,">="&'Summary KPI'!$E$5) -> 2 | P16: =SUMIFS('Data Down'!U:U,'Data Down'!D:D,'Summary KPI'!B16,'Data Down'!Q:Q,'Summary KPI'!$P$8,'Data Down'!$C:$C,"<="&'Summary KPI'!$G$5,'Data Down'!$C:$C,">="&'Summary KPI'!$E$5) -> 0 | Q16: =SUMIFS('Data Down'!N:N,'Data Down'!$D:$D,'Summary KPI'!$B16,'Data Down'!$Q:$Q,'Summary KPI'!$Q$8,'Data Down'!$C:$C,"<="&'Summary KPI'!$G$5,'Data Down'!$C:$C,">="&'Summary KPI'!$E$5) -> 0 | R16: =SUMIFS('Data Down'!N:N,'Data Down'!D:D,'Summary KPI'!B16,'Data Down'!Q:Q,'Summary KPI'!$R$8,'Data Down'!$C:$C,"<="&'Summary KPI'!$G$5,'Data Down'!$C:$C,">="&'Summary KPI'!$E$5) -> 0 | S16: =SUMIFS('Data Down'!N:N,'Data Down'!D:D,'Summary KPI'!B16,'Data Down'!Q:Q,'Summary KPI'!$S$8,'Data Down'!$C:$C,"<="&'Summary KPI'!$G$5,'Data Down'!$C:$C,">="&'Summary KPI'!$E$5) -> 13.416688 | T16: =SUMIFS('Data Down'!N:N,'Data Down'!D:D,'Summary KPI'!B16,'Data Down'!Q:Q,'Summary KPI'!$T$8,'Data Down'!$C:$C,"<="&'Summary KPI'!$G$5,'Data Down'!$C:$C,">="&'Summary KPI'!$E$5) -> 0 | U16: =+SUMIFS('Data Down'!$N:$N,'Data Down'!$D:$D,'Summary KPI'!B16,'Data Down'!$R:$R,'Summary KPI'!$U$7,'Data Down'!$C:$C,"<="&'Summary KPI'!$G$5,'Data Down'!$C:$C,">="&'Summary KPI'!$E$5) -> 0 | V16: =+SUMIFS('Data Down'!$N:$N,'Data Down'!$D:$D,'Summary KPI'!B16,'Data Down'!$R:$R,'Summary KPI'!$V$7,'Data Down'!$C:$C,"<="&'Summary KPI'!$G$5,'Data Down'!$C:$C,">="&'Summary KPI'!$E$5) -> 0 | W16: =+SUMIFS('Data Down'!$N:$N,'Data Down'!$D:$D,'Summary KPI'!B16,'Data Down'!$R:$R,'Summary KPI'!$W$7,'Data Down'!$C:$C,"<="&'Summary KPI'!$G$5,'Data Down'!$C:$C,">="&'Summary KPI'!$E$5) -> 0 | X16: =+SUMIFS('Data Down'!$N:$N,'Data Down'!$D:$D,'Summary KPI'!B16,'Data Down'!$R:$R,'Summary KPI'!$X$7,'Data Down'!$C:$C,"<="&'Summary KPI'!$G$5,'Data Down'!$C:$C,">="&'Summary KPI'!$E$5) -> 0 | Y16: =+SUMIFS('Data Down'!$N:$N,'Data Down'!$D:$D,'Summary KPI'!B16,'Data Down'!$R:$R,'Summary KPI'!$Y$7,'Data Down'!$C:$C,"<="&'Summary KPI'!$G$5,'Data Down'!$C:$C,">="&'Summary KPI'!$E$5) -> 13.416688 | Z16: =+SUMIFS('Data Down'!$N:$N,'Data Down'!$D:$D,'Summary KPI'!B16,'Data Down'!$R:$R,'Summary KPI'!$Z$7,'Data Down'!$C:$C,"<="&'Summary KPI'!$G$5,'Data Down'!$C:$C,">="&'Summary KPI'!$E$5) -> 0 | AA16: =+SUMIFS('Data Down'!$N:$N,'Data Down'!$D:$D,'Summary KPI'!B16,'Data Down'!$R:$R,'Summary KPI'!$AA$7,'Data Down'!$C:$C,"<="&'Summary KPI'!$G$5,'Data Down'!$C:$C,">="&'Summary KPI'!$E$5) -> 0 | AB16: =+SUMIFS('Data Down'!$N:$N,'Data Down'!$D:$D,'Summary KPI'!B16,'Data Down'!$R:$R,'Summary KPI'!$AB$7,'Data Down'!$C:$C,"<="&'Summary KPI'!$G$5,'Data Down'!$C:$C,">="&'Summary KPI'!$E$5) -> 0 | AC16: =+SUMIFS('Data Down'!$N:$N,'Data Down'!$D:$D,'Summary KPI'!B16,'Data Down'!$R:$R,'Summary KPI'!$AC$7,'Data Down'!$C:$C,"<="&'Summary KPI'!$G$5,'Data Down'!$C:$C,">="&'Summary KPI'!$E$5) -> 0 | AD16: =(L16-AQ16)/L16 -> 0.98136571 | AE16: =+IF(F16=0,0,F16/(F16+G16+J16)) -> 0.075 | AF16: =+IFERROR(F16/(F16+G16),0) -> 0.80098862 | AG16: =+F16/(F16+AQ16+J16) -> 0.075 | AH16: =IF(SUM(N16:O16)=0,F16,F16/SUM(N16:O16)) -> 27 | AI16: =+IF(O16=0,F16,F16/O16) -> 27 | AJ16: =IFERROR(AQ16/SUM(N16:O16),0) -> 6.7083441 | AK16: =IF(M16=0,0,M16/SUM(M16:O16)) -> 0 | AL16: =IF(N16+O16+P16=0,0,(N16+P16)/(N16+O16+P16)) -> 0 | AM16: =IF(O16+N16+P16=0,0,O16/(N16+O16+P16)) -> 1 | AN16: =IF(R16+S16=0,0,R16/(R16+S16)) -> 0 | AO16: =IF(R16+S16=0,0,S16/(R16+S16)) -> 1 | AQ16: =+SUM(Q16:S16) -> 13.416688 | AR16: =+SUM(N16:O16) -> 2 | AT16: OB x 7 Unit | AV16: 0.9 | AW16: 120 | AX16: 6
A17: =+A16+1 -> 8 | B17: DT MERCY 037 | C17: =VLOOKUP(B17,Sort!B:C,2,FALSE) -> AXOR 3336K | D17: {=INDEX(HM_Unit!D:D,MATCH('Summary KPI'!B17,HM_Unit!A:A,0))} -> 15606 | E17: {=INDEX(HM_Unit!CD:CD,MATCH('Summary KPI'!B17,HM_Unit!A:A,0))} -> 15945 | F17: =E17-D17 -> 339 | G17: =SUM(R17:S17) -> 163.06693 | H17: =Q17 -> 0 | I17: =+Z17 -> 0 | J17: =L17-F17-I17-G17-H17 -> 217.93307 | K17: =$J$5*24 -> 720 | L17: =$H$5*24 -> 720 | M17: =SUMIFS('Data Down'!U:U,'Data Down'!D:D,'Summary KPI'!B17,'Data Down'!Q:Q,'Summary KPI'!$M$8,'Data Down'!$C:$C,"<="&'Summary KPI'!$G$5,'Data Down'!$C:$C,">="&'Summary KPI'!$E$5) -> 0 | N17: =SUMIFS('Data Down'!U:U,'Data Down'!D:D,'Summary KPI'!B17,'Data Down'!Q:Q,'Summary KPI'!$N$8,'Data Down'!$C:$C,"<="&'Summary KPI'!$G$5,'Data Down'!$C:$C,">="&'Summary KPI'!$E$5) -> 2 | O17: =SUMIFS('Data Down'!U:U,'Data Down'!D:D,'Summary KPI'!B17,'Data Down'!Q:Q,'Summary KPI'!$O$8,'Data Down'!$C:$C,"<="&'Summary KPI'!$G$5,'Data Down'!$C:$C,">="&'Summary KPI'!$E$5) -> 16 | P17: =SUMIFS('Data Down'!U:U,'Data Down'!D:D,'Summary KPI'!B17,'Data Down'!Q:Q,'Summary KPI'!$P$8,'Data Down'!$C:$C,"<="&'Summary KPI'!$G$5,'Data Down'!$C:$C,">="&'Summary KPI'!$E$5) -> 0 | Q17: =SUMIFS('Data Down'!N:N,'Data Down'!$D:$D,'Summary KPI'!$B17,'Data Down'!$Q:$Q,'Summary KPI'!$Q$8,'Data Down'!$C:$C,"<="&'Summary KPI'!$G$5,'Data Down'!$C:$C,">="&'Summary KPI'!$E$5) -> 0 | R17: =SUMIFS('Data Down'!N:N,'Data Down'!D:D,'Summary KPI'!B17,'Data Down'!Q:Q,'Summary KPI'!$R$8,'Data Down'!$C:$C,"<="&'Summary KPI'!$G$5,'Data Down'!$C:$C,">="&'Summary KPI'!$E$5) -> 36.866726 | S17: =SUMIFS('Data Down'!N:N,'Data Down'!D:D,'Summary KPI'!B17,'Data Down'!Q:Q,'Summary KPI'!$S$8,'Data Down'!$C:$C,"<="&'Summary KPI'!$G$5,'Data Down'!$C:$C,">="&'Summary KPI'!$E$5) -> 126.2002 | T17: =SUMIFS('Data Down'!N:N,'Data Down'!D:D,'Summary KPI'!B17,'Data Down'!Q:Q,'Summary KPI'!$T$8,'Data Down'!$C:$C,"<="&'Summary KPI'!$G$5,'Data Down'!$C:$C,">="&'Summary KPI'!$E$5) -> 0 | U17: =+SUMIFS('Data Down'!$N:$N,'Data Down'!$D:$D,'Summary KPI'!B17,'Data Down'!$R:$R,'Summary KPI'!$U$7,'Data Down'!$C:$C,"<="&'Summary KPI'!$G$5,'Data Down'!$C:$C,">="&'Summary KPI'!$E$5) -> 0 | V17: =+SUMIFS('Data Down'!$N:$N,'Data Down'!$D:$D,'Summary KPI'!B17,'Data Down'!$R:$R,'Summary KPI'!$V$7,'Data Down'!$C:$C,"<="&'Summary KPI'!$G$5,'Data Down'!$C:$C,">="&'Summary KPI'!$E$5) -> 0 | W17: =+SUMIFS('Data Down'!$N:$N,'Data Down'!$D:$D,'Summary KPI'!B17,'Data Down'!$R:$R,'Summary KPI'!$W$7,'Data Down'!$C:$C,"<="&'Summary KPI'!$G$5,'Data Down'!$C:$C,">="&'Summary KPI'!$E$5) -> 0 | X17: =+SUMIFS('Data Down'!$N:$N,'Data Down'!$D:$D,'Summary KPI'!B17,'Data Down'!$R:$R,'Summary KPI'!$X$7,'Data Down'!$C:$C,"<="&'Summary KPI'!$G$5,'Data Down'!$C:$C,">="&'Summary KPI'!$E$5) -> 0 | Y17: =+SUMIFS('Data Down'!$N:$N,'Data Down'!$D:$D,'Summary KPI'!B17,'Data Down'!$R:$R,'Summary KPI'!$Y$7,'Data Down'!$C:$C,"<="&'Summary KPI'!$G$5,'Data Down'!$C:$C,">="&'Summary KPI'!$E$5) -> 163.06693 | Z17: =+SUMIFS('Data Down'!$N:$N,'Data Down'!$D:$D,'Summary KPI'!B17,'Data Down'!$R:$R,'Summary KPI'!$Z$7,'Data Down'!$C:$C,"<="&'Summary KPI'!$G$5,'Data Down'!$C:$C,">="&'Summary KPI'!$E$5) -> 0 | AA17: =+SUMIFS('Data Down'!$N:$N,'Data Down'!$D:$D,'Summary KPI'!B17,'Data Down'!$R:$R,'Summary KPI'!$AA$7,'Data Down'!$C:$C,"<="&'Summary KPI'!$G$5,'Data Down'!$C:$C,">="&'Summary KPI'!$E$5) -> 0 | AB17: =+SUMIFS('Data Down'!$N:$N,'Data Down'!$D:$D,'Summary KPI'!B17,'Data Down'!$R:$R,'Summary KPI'!$AB$7,'Data Down'!$C:$C,"<="&'Summary KPI'!$G$5,'Data Down'!$C:$C,">="&'Summary KPI'!$E$5) -> 0 | AC17: =+SUMIFS('Data Down'!$N:$N,'Data Down'!$D:$D,'Summary KPI'!B17,'Data Down'!$R:$R,'Summary KPI'!$AC$7,'Data Down'!$C:$C,"<="&'Summary KPI'!$G$5,'Data Down'!$C:$C,">="&'Summary KPI'!$E$5) -> 0 | AD17: =(L17-AQ17)/L17 -> 0.77351816 | AE17: =+IF(F17=0,0,F17/(F17+G17+J17)) -> 0.47083333 | AF17: =+IFERROR(F17/(F17+G17),0) -> 0.67520878 | AG17: =+F17/(F17+AQ17+J17) -> 0.47083333 | AH17: =IF(SUM(N17:O17)=0,F17,F17/SUM(N17:O17)) -> 18.833333 | AI17: =+IF(O17=0,F17,F17/O17) -> 21.1875 | AJ17: =IFERROR(AQ17/SUM(N17:O17),0) -> 9.0592738 | AK17: =IF(M17=0,0,M17/SUM(M17:O17)) -> 0 | AL17: =IF(N17+O17+P17=0,0,(N17+P17)/(N17+O17+P17)) -> 0.11111111 | AM17: =IF(O17+N17+P17=0,0,O17/(N17+O17+P17)) -> 0.88888889 | AN17: =IF(R17+S17=0,0,R17/(R17+S17)) -> 0.2260834 | AO17: =IF(R17+S17=0,0,S17/(R17+S17)) -> 0.7739166 | AQ17: =+SUM(Q17:S17) -> 163.06693 | AR17: =+SUM(N17:O17) -> 18 | AT17: OB x 30 Unit TKI | AV17: 0.9 | AW17: 120 | AX17: 6
A18: =+A17+1 -> 9 | B18: DT MERCY 038 | C18: =VLOOKUP(B18,Sort!B:C,2,FALSE) -> AXOR 3336K | D18: {=INDEX(HM_Unit!D:D,MATCH('Summary KPI'!B18,HM_Unit!A:A,0))} -> 18765 | E18: {=INDEX(HM_Unit!CD:CD,MATCH('Summary KPI'!B18,HM_Unit!A:A,0))} -> 19158 | F18: =E18-D18 -> 393 | G18: =SUM(R18:S18) -> 55.866756 | H18: =Q18 -> 0 | I18: =+Z18 -> 0 | J18: =L18-F18-I18-G18-H18 -> 271.13324 | K18: =$J$5*24 -> 720 | L18: =$H$5*24 -> 720 | M18: =SUMIFS('Data Down'!U:U,'Data Down'!D:D,'Summary KPI'!B18,'Data Down'!Q:Q,'Summary KPI'!$M$8,'Data Down'!$C:$C,"<="&'Summary KPI'!$G$5,'Data Down'!$C:$C,">="&'Summary KPI'!$E$5) -> 0 | N18: =SUMIFS('Data Down'!U:U,'Data Down'!D:D,'Summary KPI'!B18,'Data Down'!Q:Q,'Summary KPI'!$N$8,'Data Down'!$C:$C,"<="&'Summary KPI'!$G$5,'Data Down'!$C:$C,">="&'Summary KPI'!$E$5) -> 4 | O18: =SUMIFS('Data Down'!U:U,'Data Down'!D:D,'Summary KPI'!B18,'Data Down'!Q:Q,'Summary KPI'!$O$8,'Data Down'!$C:$C,"<="&'Summary KPI'!$G$5,'Data Down'!$C:$C,">="&'Summary KPI'!$E$5) -> 16 | P18: =SUMIFS('Data Down'!U:U,'Data Down'!D:D,'Summary KPI'!B18,'Data Down'!Q:Q,'Summary KPI'!$P$8,'Data Down'!$C:$C,"<="&'Summary KPI'!$G$5,'Data Down'!$C:$C,">="&'Summary KPI'!$E$5) -> 0 | Q18: =SUMIFS('Data Down'!N:N,'Data Down'!$D:$D,'Summary KPI'!$B18,'Data Down'!$Q:$Q,'Summary KPI'!$Q$8,'Data Down'!$C:$C,"<="&'Summary KPI'!$G$5,'Data Down'!$C:$C,">="&'Summary KPI'!$E$5) -> 0 | R18: =SUMIFS('Data Down'!N:N,'Data Down'!D:D,'Summary KPI'!B18,'Data Down'!Q:Q,'Summary KPI'!$R$8,'Data Down'!$C:$C,"<="&'Summary KPI'!$G$5,'Data Down'!$C:$C,">="&'Summary KPI'!$E$5) -> 3.6666725 | S18: =SUMIFS('Data Down'!N:N,'Data Down'!D:D,'Summary KPI'!B18,'Data Down'!Q:Q,'Summary KPI'!$S$8,'Data Down'!$C:$C,"<="&'Summary KPI'!$G$5,'Data Down'!$C:$C,">="&'Summary KPI'!$E$5) -> 52.200084 | T18: =SUMIFS('Data Down'!N:N,'Data Down'!D:D,'Summary KPI'!B18,'Data Down'!Q:Q,'Summary KPI'!$T$8,'Data Down'!$C:$C,"<="&'Summary KPI'!$G$5,'Data Down'!$C:$C,">="&'Summary KPI'!$E$5) -> 0 | U18: =+SUMIFS('Data Down'!$N:$N,'Data Down'!$D:$D,'Summary KPI'!B18,'Data Down'!$R:$R,'Summary KPI'!$U$7,'Data Down'!$C:$C,"<="&'Summary KPI'!$G$5,'Data Down'!$C:$C,">="&'Summary KPI'!$E$5) -> 0 | V18: =+SUMIFS('Data Down'!$N:$N,'Data Down'!$D:$D,'Summary KPI'!B18,'Data Down'!$R:$R,'Summary KPI'!$V$7,'Data Down'!$C:$C,"<="&'Summary KPI'!$G$5,'Data Down'!$C:$C,">="&'Summary KPI'!$E$5) -> 0 | W18: =+SUMIFS('Data Down'!$N:$N,'Data Down'!$D:$D,'Summary KPI'!B18,'Data Down'!$R:$R,'Summary KPI'!$W$7,'Data Down'!$C:$C,"<="&'Summary KPI'!$G$5,'Data Down'!$C:$C,">="&'Summary KPI'!$E$5) -> 0 | X18: =+SUMIFS('Data Down'!$N:$N,'Data Down'!$D:$D,'Summary KPI'!B18,'Data Down'!$R:$R,'Summary KPI'!$X$7,'Data Down'!$C:$C,"<="&'Summary KPI'!$G$5,'Data Down'!$C:$C,">="&'Summary KPI'!$E$5) -> 0 | Y18: =+SUMIFS('Data Down'!$N:$N,'Data Down'!$D:$D,'Summary KPI'!B18,'Data Down'!$R:$R,'Summary KPI'!$Y$7,'Data Down'!$C:$C,"<="&'Summary KPI'!$G$5,'Data Down'!$C:$C,">="&'Summary KPI'!$E$5) -> 55.866756 | Z18: =+SUMIFS('Data Down'!$N:$N,'Data Down'!$D:$D,'Summary KPI'!B18,'Data Down'!$R:$R,'Summary KPI'!$Z$7,'Data Down'!$C:$C,"<="&'Summary KPI'!$G$5,'Data Down'!$C:$C,">="&'Summary KPI'!$E$5) -> 0 | AA18: =+SUMIFS('Data Down'!$N:$N,'Data Down'!$D:$D,'Summary KPI'!B18,'Data Down'!$R:$R,'Summary KPI'!$AA$7,'Data Down'!$C:$C,"<="&'Summary KPI'!$G$5,'Data Down'!$C:$C,">="&'Summary KPI'!$E$5) -> 0 | AB18: =+SUMIFS('Data Down'!$N:$N,'Data Down'!$D:$D,'Summary KPI'!B18,'Data Down'!$R:$R,'Summary KPI'!$AB$7,'Data Down'!$C:$C,"<="&'Summary KPI'!$G$5,'Data Down'!$C:$C,">="&'Summary KPI'!$E$5) -> 0 | AC18: =+SUMIFS('Data Down'!$N:$N,'Data Down'!$D:$D,'Summary KPI'!B18,'Data Down'!$R:$R,'Summary KPI'!$AC$7,'Data Down'!$C:$C,"<="&'Summary KPI'!$G$5,'Data Down'!$C:$C,">="&'Summary KPI'!$E$5) -> 0 | AD18: =(L18-AQ18)/L18 -> 0.92240728 | AE18: =+IF(F18=0,0,F18/(F18+G18+J18)) -> 0.54583333 | AF18: =+IFERROR(F18/(F18+G18),0) -> 0.87553822 | AG18: =+F18/(F18+AQ18+J18) -> 0.54583333 | AH18: =IF(SUM(N18:O18)=0,F18,F18/SUM(N18:O18)) -> 19.65 | AI18: =+IF(O18=0,F18,F18/O18) -> 24.5625 | AJ18: =IFERROR(AQ18/SUM(N18:O18),0) -> 2.7933378 | AK18: =IF(M18=0,0,M18/SUM(M18:O18)) -> 0 | AL18: =IF(N18+O18+P18=0,0,(N18+P18)/(N18+O18+P18)) -> 0.2 | AM18: =IF(O18+N18+P18=0,0,O18/(N18+O18+P18)) -> 0.8 | AN18: =IF(R18+S18=0,0,R18/(R18+S18)) -> 0.065632458 | AO18: =IF(R18+S18=0,0,S18/(R18+S18)) -> 0.93436754 | AQ18: =+SUM(Q18:S18) -> 55.866756 | AR18: =+SUM(N18:O18) -> 20 | AT18: OB x 30 Unit TKI | AV18: 0.9 | AW18: 120 | AX18: 6
A19: =+A18+1 -> 10 | B19: DT MERCY 039 | C19: =VLOOKUP(B19,Sort!B:C,2,FALSE) -> AXOR 3336K | D19: {=INDEX(HM_Unit!D:D,MATCH('Summary KPI'!B19,HM_Unit!A:A,0))} -> 18054 | E19: {=INDEX(HM_Unit!CD:CD,MATCH('Summary KPI'!B19,HM_Unit!A:A,0))} -> 18302 | F19: =E19-D19 -> 248 | G19: =SUM(R19:S19) -> 260.33375 | H19: =Q19 -> 0 | I19: =+Z19 -> 0 | J19: =L19-F19-I19-G19-H19 -> 211.66625 | K19: =$J$5*24 -> 720 | L19: =$H$5*24 -> 720 | M19: =SUMIFS('Data Down'!U:U,'Data Down'!D:D,'Summary KPI'!B19,'Data Down'!Q:Q,'Summary KPI'!$M$8,'Data Down'!$C:$C,"<="&'Summary KPI'!$G$5,'Data Down'!$C:$C,">="&'Summary KPI'!$E$5) -> 0 | N19: =SUMIFS('Data Down'!U:U,'Data Down'!D:D,'Summary KPI'!B19,'Data Down'!Q:Q,'Summary KPI'!$N$8,'Data Down'!$C:$C,"<="&'Summary KPI'!$G$5,'Data Down'!$C:$C,">="&'Summary KPI'!$E$5) -> 3 | O19: =SUMIFS('Data Down'!U:U,'Data Down'!D:D,'Summary KPI'!B19,'Data Down'!Q:Q,'Summary KPI'!$O$8,'Data Down'!$C:$C,"<="&'Summary KPI'!$G$5,'Data Down'!$C:$C,">="&'Summary KPI'!$E$5) -> 15 | P19: =SUMIFS('Data Down'!U:U,'Data Down'!D:D,'Summary KPI'!B19,'Data Down'!Q:Q,'Summary KPI'!$P$8,'Data Down'!$C:$C,"<="&'Summary KPI'!$G$5,'Data Down'!$C:$C,">="&'Summary KPI'!$E$5) -> 0 | Q19: =SUMIFS('Data Down'!N:N,'Data Down'!$D:$D,'Summary KPI'!$B19,'Data Down'!$Q:$Q,'Summary KPI'!$Q$8,'Data Down'!$C:$C,"<="&'Summary KPI'!$G$5,'Data Down'!$C:$C,">="&'Summary KPI'!$E$5) -> 0 | R19: =SUMIFS('Data Down'!N:N,'Data Down'!D:D,'Summary KPI'!B19,'Data Down'!Q:Q,'Summary KPI'!$R$8,'Data Down'!$C:$C,"<="&'Summary KPI'!$G$5,'Data Down'!$C:$C,">="&'Summary KPI'!$E$5) -> 8.9000142 | S19: =SUMIFS('Data Down'!N:N,'Data Down'!D:D,'Summary KPI'!B19,'Data Down'!Q:Q,'Summary KPI'!$S$8,'Data Down'!$C:$C,"<="&'Summary KPI'!$G$5,'Data Down'!$C:$C,">="&'Summary KPI'!$E$5) -> 251.43374 | T19: =SUMIFS('Data Down'!N:N,'Data Down'!D:D,'Summary KPI'!B19,'Data Down'!Q:Q,'Summary KPI'!$T$8,'Data Down'!$C:$C,"<="&'Summary KPI'!$G$5,'Data Down'!$C:$C,">="&'Summary KPI'!$E$5) -> 0 | U19: =+SUMIFS('Data Down'!$N:$N,'Data Down'!$D:$D,'Summary KPI'!B19,'Data Down'!$R:$R,'Summary KPI'!$U$7,'Data Down'!$C:$C,"<="&'Summary KPI'!$G$5,'Data Down'!$C:$C,">="&'Summary KPI'!$E$5) -> 0 | V19: =+SUMIFS('Data Down'!$N:$N,'Data Down'!$D:$D,'Summary KPI'!B19,'Data Down'!$R:$R,'Summary KPI'!$V$7,'Data Down'!$C:$C,"<="&'Summary KPI'!$G$5,'Data Down'!$C:$C,">="&'Summary KPI'!$E$5) -> 0 | W19: =+SUMIFS('Data Down'!$N:$N,'Data Down'!$D:$D,'Summary KPI'!B19,'Data Down'!$R:$R,'Summary KPI'!$W$7,'Data Down'!$C:$C,"<="&'Summary KPI'!$G$5,'Data Down'!$C:$C,">="&'Summary KPI'!$E$5) -> 0 | X19: =+SUMIFS('Data Down'!$N:$N,'Data Down'!$D:$D,'Summary KPI'!B19,'Data Down'!$R:$R,'Summary KPI'!$X$7,'Data Down'!$C:$C,"<="&'Summary KPI'!$G$5,'Data Down'!$C:$C,">="&'Summary KPI'!$E$5) -> 0 | Y19: =+SUMIFS('Data Down'!$N:$N,'Data Down'!$D:$D,'Summary KPI'!B19,'Data Down'!$R:$R,'Summary KPI'!$Y$7,'Data Down'!$C:$C,"<="&'Summary KPI'!$G$5,'Data Down'!$C:$C,">="&'Summary KPI'!$E$5) -> 260.33375 | Z19: =+SUMIFS('Data Down'!$N:$N,'Data Down'!$D:$D,'Summary KPI'!B19,'Data Down'!$R:$R,'Summary KPI'!$Z$7,'Data Down'!$C:$C,"<="&'Summary KPI'!$G$5,'Data Down'!$C:$C,">="&'Summary KPI'!$E$5) -> 0 | AA19: =+SUMIFS('Data Down'!$N:$N,'Data Down'!$D:$D,'Summary KPI'!B19,'Data Down'!$R:$R,'Summary KPI'!$AA$7,'Data Down'!$C:$C,"<="&'Summary KPI'!$G$5,'Data Down'!$C:$C,">="&'Summary KPI'!$E$5) -> 0 | AB19: =+SUMIFS('Data Down'!$N:$N,'Data Down'!$D:$D,'Summary KPI'!B19,'Data Down'!$R:$R,'Summary KPI'!$AB$7,'Data Down'!$C:$C,"<="&'Summary KPI'!$G$5,'Data Down'!$C:$C,">="&'Summary KPI'!$E$5) -> 0 | AC19: =+SUMIFS('Data Down'!$N:$N,'Data Down'!$D:$D,'Summary KPI'!B19,'Data Down'!$R:$R,'Summary KPI'!$AC$7,'Data Down'!$C:$C,"<="&'Summary KPI'!$G$5,'Data Down'!$C:$C,">="&'Summary KPI'!$E$5) -> 0 | AD19: =(L19-AQ19)/L19 -> 0.63842535 | AE19: =+IF(F19=0,0,F19/(F19+G19+J19)) -> 0.34444444 | AF19: =+IFERROR(F19/(F19+G19),0) -> 0.48786845 | AG19: =+F19/(F19+AQ19+J19) -> 0.34444444 | AH19: =IF(SUM(N19:O19)=0,F19,F19/SUM(N19:O19)) -> 13.777778 | AI19: =+IF(O19=0,F19,F19/O19) -> 16.533333 | AJ19: =IFERROR(AQ19/SUM(N19:O19),0) -> 14.462986 | AK19: =IF(M19=0,0,M19/SUM(M19:O19)) -> 0 | AL19: =IF(N19+O19+P19=0,0,(N19+P19)/(N19+O19+P19)) -> 0.16666667 | AM19: =IF(O19+N19+P19=0,0,O19/(N19+O19+P19)) -> 0.83333333 | AN19: =IF(R19+S19=0,0,R19/(R19+S19)) -> 0.03418694 | AO19: =IF(R19+S19=0,0,S19/(R19+S19)) -> 0.96581306 | AQ19: =+SUM(Q19:S19) -> 260.33375 | AR19: =+SUM(N19:O19) -> 18 | AT19: OB x 30 Unit TKI | AV19: 0.9 | AW19: 120 | AX19: 6
A20: =+A19+1 -> 11 | B20: DT MERCY 040 | C20: =VLOOKUP(B20,Sort!B:C,2,FALSE) -> AXOR 3336K | D20: {=INDEX(HM_Unit!D:D,MATCH('Summary KPI'!B20,HM_Unit!A:A,0))} -> 17501 | E20: {=INDEX(HM_Unit!CD:CD,MATCH('Summary KPI'!B20,HM_Unit!A:A,0))} -> 17890 | F20: =E20-D20 -> 389 | G20: =SUM(R20:S20) -> 60.700097 | H20: =Q20 -> 0 | I20: =+Z20 -> 0 | J20: =L20-F20-I20-G20-H20 -> 270.2999 | K20: =$J$5*24 -> 720 | L20: =$H$5*24 -> 720 | M20: =SUMIFS('Data Down'!U:U,'Data Down'!D:D,'Summary KPI'!B20,'Data Down'!Q:Q,'Summary KPI'!$M$8,'Data Down'!$C:$C,"<="&'Summary KPI'!$G$5,'Data Down'!$C:$C,">="&'Summary KPI'!$E$5) -> 0 | N20: =SUMIFS('Data Down'!U:U,'Data Down'!D:D,'Summary KPI'!B20,'Data Down'!Q:Q,'Summary KPI'!$N$8,'Data Down'!$C:$C,"<="&'Summary KPI'!$G$5,'Data Down'!$C:$C,">="&'Summary KPI'!$E$5) -> 5 | O20: =SUMIFS('Data Down'!U:U,'Data Down'!D:D,'Summary KPI'!B20,'Data Down'!Q:Q,'Summary KPI'!$O$8,'Data Down'!$C:$C,"<="&'Summary KPI'!$G$5,'Data Down'!$C:$C,">="&'Summary KPI'!$E$5) -> 26 | P20: =SUMIFS('Data Down'!U:U,'Data Down'!D:D,'Summary KPI'!B20,'Data Down'!Q:Q,'Summary KPI'!$P$8,'Data Down'!$C:$C,"<="&'Summary KPI'!$G$5,'Data Down'!$C:$C,">="&'Summary KPI'!$E$5) -> 0 | Q20: =SUMIFS('Data Down'!N:N,'Data Down'!$D:$D,'Summary KPI'!$B20,'Data Down'!$Q:$Q,'Summary KPI'!$Q$8,'Data Down'!$C:$C,"<="&'Summary KPI'!$G$5,'Data Down'!$C:$C,">="&'Summary KPI'!$E$5) -> 0 | R20: =SUMIFS('Data Down'!N:N,'Data Down'!D:D,'Summary KPI'!B20,'Data Down'!Q:Q,'Summary KPI'!$R$8,'Data Down'!$C:$C,"<="&'Summary KPI'!$G$5,'Data Down'!$C:$C,">="&'Summary KPI'!$E$5) -> 14.800024 | S20: =SUMIFS('Data Down'!N:N,'Data Down'!D:D,'Summary KPI'!B20,'Data Down'!Q:Q,'Summary KPI'!$S$8,'Data Down'!$C:$C,"<="&'Summary KPI'!$G$5,'Data Down'!$C:$C,">="&'Summary KPI'!$E$5) -> 45.900073 | T20: =SUMIFS('Data Down'!N:N,'Data Down'!D:D,'Summary KPI'!B20,'Data Down'!Q:Q,'Summary KPI'!$T$8,'Data Down'!$C:$C,"<="&'Summary KPI'!$G$5,'Data Down'!$C:$C,">="&'Summary KPI'!$E$5) -> 0 | U20: =+SUMIFS('Data Down'!$N:$N,'Data Down'!$D:$D,'Summary KPI'!B20,'Data Down'!$R:$R,'Summary KPI'!$U$7,'Data Down'!$C:$C,"<="&'Summary KPI'!$G$5,'Data Down'!$C:$C,">="&'Summary KPI'!$E$5) -> 0 | V20: =+SUMIFS('Data Down'!$N:$N,'Data Down'!$D:$D,'Summary KPI'!B20,'Data Down'!$R:$R,'Summary KPI'!$V$7,'Data Down'!$C:$C,"<="&'Summary KPI'!$G$5,'Data Down'!$C:$C,">="&'Summary KPI'!$E$5) -> 0 | W20: =+SUMIFS('Data Down'!$N:$N,'Data Down'!$D:$D,'Summary KPI'!B20,'Data Down'!$R:$R,'Summary KPI'!$W$7,'Data Down'!$C:$C,"<="&'Summary KPI'!$G$5,'Data Down'!$C:$C,">="&'Summary KPI'!$E$5) -> 0 | X20: =+SUMIFS('Data Down'!$N:$N,'Data Down'!$D:$D,'Summary KPI'!B20,'Data Down'!$R:$R,'Summary KPI'!$X$7,'Data Down'!$C:$C,"<="&'Summary KPI'!$G$5,'Data Down'!$C:$C,">="&'Summary KPI'!$E$5) -> 0 | Y20: =+SUMIFS('Data Down'!$N:$N,'Data Down'!$D:$D,'Summary KPI'!B20,'Data Down'!$R:$R,'Summary KPI'!$Y$7,'Data Down'!$C:$C,"<="&'Summary KPI'!$G$5,'Data Down'!$C:$C,">="&'Summary KPI'!$E$5) -> 60.700097 | Z20: =+SUMIFS('Data Down'!$N:$N,'Data Down'!$D:$D,'Summary KPI'!B20,'Data Down'!$R:$R,'Summary KPI'!$Z$7,'Data Down'!$C:$C,"<="&'Summary KPI'!$G$5,'Data Down'!$C:$C,">="&'Summary KPI'!$E$5) -> 0 | AA20: =+SUMIFS('Data Down'!$N:$N,'Data Down'!$D:$D,'Summary KPI'!B20,'Data Down'!$R:$R,'Summary KPI'!$AA$7,'Data Down'!$C:$C,"<="&'Summary KPI'!$G$5,'Data Down'!$C:$C,">="&'Summary KPI'!$E$5) -> 0 | AB20: =+SUMIFS('Data Down'!$N:$N,'Data Down'!$D:$D,'Summary KPI'!B20,'Data Down'!$R:$R,'Summary KPI'!$AB$7,'Data Down'!$C:$C,"<="&'Summary KPI'!$G$5,'Data Down'!$C:$C,">="&'Summary KPI'!$E$5) -> 0 | AC20: =+SUMIFS('Data Down'!$N:$N,'Data Down'!$D:$D,'Summary KPI'!B20,'Data Down'!$R:$R,'Summary KPI'!$AC$7,'Data Down'!$C:$C,"<="&'Summary KPI'!$G$5,'Data Down'!$C:$C,">="&'Summary KPI'!$E$5) -> 0 | AD20: =(L20-AQ20)/L20 -> 0.91569431 | AE20: =+IF(F20=0,0,F20/(F20+G20+J20)) -> 0.54027778 | AF20: =+IFERROR(F20/(F20+G20),0) -> 0.86502094 | AG20: =+F20/(F20+AQ20+J20) -> 0.54027778 | AH20: =IF(SUM(N20:O20)=0,F20,F20/SUM(N20:O20)) -> 12.548387 | AI20: =+IF(O20=0,F20,F20/O20) -> 14.961538 | AJ20: =IFERROR(AQ20/SUM(N20:O20),0) -> 1.9580676 | AK20: =IF(M20=0,0,M20/SUM(M20:O20)) -> 0 | AL20: =IF(N20+O20+P20=0,0,(N20+P20)/(N20+O20+P20)) -> 0.16129032 | AM20: =IF(O20+N20+P20=0,0,O20/(N20+O20+P20)) -> 0.83870968 | AN20: =IF(R20+S20=0,0,R20/(R20+S20)) -> 0.24382208 | AO20: =IF(R20+S20=0,0,S20/(R20+S20)) -> 0.75617792 | AQ20: =+SUM(Q20:S20) -> 60.700097 | AR20: =+SUM(N20:O20) -> 31 | AT20: OB x 30 Unit TKI | AV20: 0.9 | AW20: 120 | AX20: 6
A21: =+A20+1 -> 12 | B21: DT MERCY 041 | C21: =VLOOKUP(B21,Sort!B:C,2,FALSE) -> AXOR 3336K | D21: {=INDEX(HM_Unit!D:D,MATCH('Summary KPI'!B21,HM_Unit!A:A,0))} -> 17922 | E21: {=INDEX(HM_Unit!CD:CD,MATCH('Summary KPI'!B21,HM_Unit!A:A,0))} -> 18308 | F21: =E21-D21 -> 386 | G21: =SUM(R21:S21) -> 34.916723 | H21: =Q21 -> 0 | I21: =+Z21 -> 0 | J21: =L21-F21-I21-G21-H21 -> 299.08328 | K21: =$J$5*24 -> 720 | L21: =$H$5*24 -> 720 | M21: =SUMIFS('Data Down'!U:U,'Data Down'!D:D,'Summary KPI'!B21,'Data Down'!Q:Q,'Summary KPI'!$M$8,'Data Down'!$C:$C,"<="&'Summary KPI'!$G$5,'Data Down'!$C:$C,">="&'Summary KPI'!$E$5) -> 0 | N21: =SUMIFS('Data Down'!U:U,'Data Down'!D:D,'Summary KPI'!B21,'Data Down'!Q:Q,'Summary KPI'!$N$8,'Data Down'!$C:$C,"<="&'Summary KPI'!$G$5,'Data Down'!$C:$C,">="&'Summary KPI'!$E$5) -> 5 | O21: =SUMIFS('Data Down'!U:U,'Data Down'!D:D,'Summary KPI'!B21,'Data Down'!Q:Q,'Summary KPI'!$O$8,'Data Down'!$C:$C,"<="&'Summary KPI'!$G$5,'Data Down'!$C:$C,">="&'Summary KPI'!$E$5) -> 17 | P21: =SUMIFS('Data Down'!U:U,'Data Down'!D:D,'Summary KPI'!B21,'Data Down'!Q:Q,'Summary KPI'!$P$8,'Data Down'!$C:$C,"<="&'Summary KPI'!$G$5,'Data Down'!$C:$C,">="&'Summary KPI'!$E$5) -> 0 | Q21: =SUMIFS('Data Down'!N:N,'Data Down'!$D:$D,'Summary KPI'!$B21,'Data Down'!$Q:$Q,'Summary KPI'!$Q$8,'Data Down'!$C:$C,"<="&'Summary KPI'!$G$5,'Data Down'!$C:$C,">="&'Summary KPI'!$E$5) -> 0 | R21: =SUMIFS('Data Down'!N:N,'Data Down'!D:D,'Summary KPI'!B21,'Data Down'!Q:Q,'Summary KPI'!$R$8,'Data Down'!$C:$C,"<="&'Summary KPI'!$G$5,'Data Down'!$C:$C,">="&'Summary KPI'!$E$5) -> 10.700017 | S21: =SUMIFS('Data Down'!N:N,'Data Down'!D:D,'Summary KPI'!B21,'Data Down'!Q:Q,'Summary KPI'!$S$8,'Data Down'!$C:$C,"<="&'Summary KPI'!$G$5,'Data Down'!$C:$C,">="&'Summary KPI'!$E$5) -> 24.216705 | T21: =SUMIFS('Data Down'!N:N,'Data Down'!D:D,'Summary KPI'!B21,'Data Down'!Q:Q,'Summary KPI'!$T$8,'Data Down'!$C:$C,"<="&'Summary KPI'!$G$5,'Data Down'!$C:$C,">="&'Summary KPI'!$E$5) -> 0 | U21: =+SUMIFS('Data Down'!$N:$N,'Data Down'!$D:$D,'Summary KPI'!B21,'Data Down'!$R:$R,'Summary KPI'!$U$7,'Data Down'!$C:$C,"<="&'Summary KPI'!$G$5,'Data Down'!$C:$C,">="&'Summary KPI'!$E$5) -> 0 | V21: =+SUMIFS('Data Down'!$N:$N,'Data Down'!$D:$D,'Summary KPI'!B21,'Data Down'!$R:$R,'Summary KPI'!$V$7,'Data Down'!$C:$C,"<="&'Summary KPI'!$G$5,'Data Down'!$C:$C,">="&'Summary KPI'!$E$5) -> 0 | W21: =+SUMIFS('Data Down'!$N:$N,'Data Down'!$D:$D,'Summary KPI'!B21,'Data Down'!$R:$R,'Summary KPI'!$W$7,'Data Down'!$C:$C,"<="&'Summary KPI'!$G$5,'Data Down'!$C:$C,">="&'Summary KPI'!$E$5) -> 0 | X21: =+SUMIFS('Data Down'!$N:$N,'Data Down'!$D:$D,'Summary KPI'!B21,'Data Down'!$R:$R,'Summary KPI'!$X$7,'Data Down'!$C:$C,"<="&'Summary KPI'!$G$5,'Data Down'!$C:$C,">="&'Summary KPI'!$E$5) -> 0 | Y21: =+SUMIFS('Data Down'!$N:$N,'Data Down'!$D:$D,'Summary KPI'!B21,'Data Down'!$R:$R,'Summary KPI'!$Y$7,'Data Down'!$C:$C,"<="&'Summary KPI'!$G$5,'Data Down'!$C:$C,">="&'Summary KPI'!$E$5) -> 34.916723 | Z21: =+SUMIFS('Data Down'!$N:$N,'Data Down'!$D:$D,'Summary KPI'!B21,'Data Down'!$R:$R,'Summary KPI'!$Z$7,'Data Down'!$C:$C,"<="&'Summary KPI'!$G$5,'Data Down'!$C:$C,">="&'Summary KPI'!$E$5) -> 0 | AA21: =+SUMIFS('Data Down'!$N:$N,'Data Down'!$D:$D,'Summary KPI'!B21,'Data Down'!$R:$R,'Summary KPI'!$AA$7,'Data Down'!$C:$C,"<="&'Summary KPI'!$G$5,'Data Down'!$C:$C,">="&'Summary KPI'!$E$5) -> 0 | AB21: =+SUMIFS('Data Down'!$N:$N,'Data Down'!$D:$D,'Summary KPI'!B21,'Data Down'!$R:$R,'Summary KPI'!$AB$7,'Data Down'!$C:$C,"<="&'Summary KPI'!$G$5,'Data Down'!$C:$C,">="&'Summary KPI'!$E$5) -> 0 | AC21: =+SUMIFS('Data Down'!$N:$N,'Data Down'!$D:$D,'Summary KPI'!B21,'Data Down'!$R:$R,'Summary KPI'!$AC$7,'Data Down'!$C:$C,"<="&'Summary KPI'!$G$5,'Data Down'!$C:$C,">="&'Summary KPI'!$E$5) -> 0 | AD21: =(L21-AQ21)/L21 -> 0.95150455 | AE21: =+IF(F21=0,0,F21/(F21+G21+J21)) -> 0.53611111 | AF21: =+IFERROR(F21/(F21+G21),0) -> 0.91704601 | AG21: =+F21/(F21+AQ21+J21) -> 0.53611111 | AH21: =IF(SUM(N21:O21)=0,F21,F21/SUM(N21:O21)) -> 17.545455 | AI21: =+IF(O21=0,F21,F21/O21) -> 22.705882 | AJ21: =IFERROR(AQ21/SUM(N21:O21),0) -> 1.5871238 | AK21: =IF(M21=0,0,M21/SUM(M21:O21)) -> 0 | AL21: =IF(N21+O21+P21=0,0,(N21+P21)/(N21+O21+P21)) -> 0.22727273 | AM21: =IF(O21+N21+P21=0,0,O21/(N21+O21+P21)) -> 0.77272727 | AN21: =IF(R21+S21=0,0,R21/(R21+S21)) -> 0.30644391 | AO21: =IF(R21+S21=0,0,S21/(R21+S21)) -> 0.69355609 | AQ21: =+SUM(Q21:S21) -> 34.916723 | AR21: =+SUM(N21:O21) -> 22 | AT21: OB x 30 Unit TKI | AV21: 0.9 | AW21: 120 | AX21: 6
